Workbook

Sheet 00_РЕЗЮМЕ
A1: VARSHAVKA — Сценарий S03
A2: Банкетный день: дневная работа до 17:00; а-ля карт 20%; бизнес-ланч, доставка и самовывоз 100%; ужины гостиницы 50% от завтраков.
A4: ПАСПОРТ МОДЕЛИ
A5: Начало периода | B5: 01.09.2026 | D5: Окончание периода | E5: 31.08.2027
A6: Площадь кафе, м² | B6: ='01_ВВОД'!$D$7 | D6: Посадочных мест | E6: ='01_ВВОД'!$D$10
A7: Аренда, руб./мес. | B7: ='01_ВВОД'!$D$9 | D7: Банкетов за год | E7: ='01_ВВОД'!$D$52
A9: КЛЮЧЕВЫЕ РЕЗУЛЬТАТЫ
A10: Показатель | B10: За операционный год | C10: Среднее за месяц | E10: Показатель | F10: Значение
A11: Доходы кафе | B11: ='07_PNL_НАЛОГИ'!P6 | C11: ='07_PNL_НАЛОГИ'!Q6 | E11: Валовая маржа кафе | F11: =IF('07_PNL_НАЛОГИ'!P6=0,0,'07_PNL_НАЛОГИ'!P8/'07_PNL_НАЛОГИ'!P6)
A12: Прибыль кафе до налога | B12: ='07_PNL_НАЛОГИ'!P20 | C12: ='07_PNL_НАЛОГИ'!Q20 | E12: Маржинальность кафе | F12: =IF('07_PNL_НАЛОГИ'!P6=0,0,'07_PNL_НАЛОГИ'!P10/'07_PNL_НАЛОГИ'!P6)
A13: Чистый результат кафе | B13: ='07_PNL_НАЛОГИ'!P40 | C13: ='07_PNL_НАЛОГИ'!Q40 | E13: ФОТ / доходы кафе | F13: =IF('07_PNL_НАЛОГИ'!P6=0,0,'07_PNL_НАЛОГИ'!P11/'07_PNL_НАЛОГИ'!P6)
A14: Доходы банкетов | B14: ='07_PNL_НАЛОГИ'!P25 | C14: ='07_PNL_НАЛОГИ'!Q25 | E14: Чистая рентабельность кафе | F14: =IF('07_PNL_НАЛОГИ'!P6=0,0,'07_PNL_НАЛОГИ'!P40/'07_PNL_НАЛОГИ'!P6)
A15: Прибыль банкетов до налога | B15: ='07_PNL_НАЛОГИ'!P29 | C15: ='07_PNL_НАЛОГИ'!Q29 | E15: Рентабельность банкетов до налога | F15: =IF('07_PNL_НАЛОГИ'!P25=0,0,'07_PNL_НАЛОГИ'!P29/'07_PNL_НАЛОГИ'!P25)
A16: Чистый результат банкетов | B16: ='07_PNL_НАЛОГИ'!P41 | C16: ='07_PNL_НАЛОГИ'!Q41 | E16: Упущенные доходы кафе из-за банкетов | F16: ='03_ДОХОДЫ'!P30
A17: Совокупные доходы проекта | B17: ='07_PNL_НАЛОГИ'!P33 | C17: ='07_PNL_НАЛОГИ'!Q33 | E17: Доходы кафе на 1 м² | F17: =IF('01_ВВОД'!$D$7=0,0,'07_PNL_НАЛОГИ'!P6/'01_ВВОД'!$D$7)
A18: Налог к уплате | B18: ='07_PNL_НАЛОГИ'!P37 | C18: ='07_PNL_НАЛОГИ'!Q37 | E18: Гостиничных заказов за год | F18: ='03_ДОХОДЫ'!P22
A19: Чистая прибыль проекта | B19: ='07_PNL_НАЛОГИ'!P42 | C19: ='07_PNL_НАЛОГИ'!Q42
A22: ПОМЕСЯЧНЫЙ ЧИСТЫЙ РЕЗУЛЬТАТ
A23: Показатель | B23: Сен-26 | C23: Окт-26 | D23: Ноя-26 | E23: Дек-26 | F23: Янв-27 | G23: Фев-27 | H23: Мар-27 | I23: Апр-27 | J23: Май-27 | K23: Июн-27 | L23: Июл-27 | M23: Авг-27
A24: Кафе | B24: ='07_PNL_НАЛОГИ'!D40 | C24: ='07_PNL_НАЛОГИ'!E40 | D24: ='07_PNL_НАЛОГИ'!F40 | E24: ='07_PNL_НАЛОГИ'!G40 | F24: ='07_PNL_НАЛОГИ'!H40 | G24: ='07_PNL_НАЛОГИ'!I40 | H24: ='07_PNL_НАЛОГИ'!J40 | I24: ='07_PNL_НАЛОГИ'!K40 | ... M24: ='07_PNL_НАЛОГИ'!O40
A25: Банкеты | B25: ='07_PNL_НАЛОГИ'!D41 | C25: ='07_PNL_НАЛОГИ'!E41 | D25: ='07_PNL_НАЛОГИ'!F41 | E25: ='07_PNL_НАЛОГИ'!G41 | F25: ='07_PNL_НАЛОГИ'!H41 | G25: ='07_PNL_НАЛОГИ'!I41 | H25: ='07_PNL_НАЛОГИ'!J41 | I25: ='07_PNL_НАЛОГИ'!K41 | ... M25: ='07_PNL_НАЛОГИ'!O41
A26: Проект | B26: ='07_PNL_НАЛОГИ'!D42 | C26: ='07_PNL_НАЛОГИ'!E42 | D26: ='07_PNL_НАЛОГИ'!F42 | E26: ='07_PNL_НАЛОГИ'!G42 | F26: ='07_PNL_НАЛОГИ'!H42 | G26: ='07_PNL_НАЛОГИ'!I42 | H26: ='07_PNL_НАЛОГИ'!J42 | I26: ='07_PNL_НАЛОГИ'!K42 | ... M26: ='07_PNL_НАЛОГИ'!O42
A29: ВАЖНЫЕ ДОПУЩЕНИЯ
A30: 1 | B30: Праздничные переносы 2027 года в календаре требуют обновления после официального утверждения.
A31: 2 | B31: НДС в модели установлен 0%; налоговую схему необходимо подтвердить отдельно.
A32: 3 | B32: Оценочные расходы USALI выделены в 01_ВВОД и могут быть заменены без изменения формул.
A33: 4 | B33: Налог УСН рассчитан консолидированно; распределение между кафе и банкетами — управленческое, по выручке.

Sheet 01_ВВОД
A1: VARSHAVKA — исходные данные операционной модели
A2: Операционный год: сентябрь 2026 — август 2027. Синие ячейки — изменяемые входные данные; жёлтая/оранжевая заливка — допущения, требующие проверки.
A4: Код | B4: Раздел | C4: Параметр | D4: Значение | E4: Ед. | F4: Статус | G4: Источник / комментарий
A5: START_DATE | B5: Проект | C5: Начало операционной деятельности | D5: 46266 | E5: дата | F5: Подтверждено | G5: Пользователь
A6: END_DATE | B6: Проект | C6: Окончание операционного года | D6: 46630 | E6: дата | F6: Расчёт | G6: 12 месяцев от старта
A7: AREA | B7: Объект | C7: Площадь помещений №19, №20, №39 | D7: 80.9 | E7: м² | F7: Подтверждено | G7: Схема помещений №19, №20, №39; https://drive.google.com/drive/folders/1VLrgg-vLogvAVUFPkVmkNqlbE9rJ0BNx?usp=drive_link
A8: RENT_RATE | B8: Объект | C8: Ставка аренды | D8: 1000 | E8: руб./м²/мес. | F8: Подтверждено | G8: Пользователь
A9: RENT_MONTH | B9: Объект | C9: Арендный платёж в месяц | D9: =D7*D8 | E9: руб./мес. | F9: Расчёт | G9: Площадь × ставка
A10: SEATS | B10: Объект | C10: Расчётное число посадочных мест | D10: 20 | E10: мест | F10: Подтверждено | G10: Пользователь
A11: MAX_SEATS | B11: Объект | C11: Максимальное число мест | D11: 26 | E11: мест | F11: Подтверждено | G11: Пользователь
A12: USN_RATE | B12: Налоги | C12: УСН «Доходы минус расходы» | D12: 0.15 | E12: % | F12: Подтверждено | G12: Пользователь; справочно: https://www.nalog.gov.ru/rn77/taxation/taxes/usn/
A13: MIN_TAX_RATE | B13: Налоги | C13: Минимальный налог УСН | D13: 0.01 | E13: % | F13: Методика | G13: https://www.nalog.gov.ru/rn77/taxation/taxes/usn/
A14: ACQ_RATE | B14: Налоги и комиссии | C14: Эквайринг | D14: 0.015 | E14: % выручки | F14: Подтверждено | G14: Пользователь
A15: VAT_RATE | B15: Налоги | C15: НДС в модели | D15: 0 | E15: % | F15: Требует решения | G15: Пока 0%; проверить: https://www.nalog.gov.ru/rn77/taxation/taxes/nds_usn/
A16: SPOILAGE_RATE | B16: Себестоимость | C16: Списания и порча | D16: 0.015 | E16: % food cost | F16: Допущение | G16: Рабочий резерв
A17: INV_DIFF_RATE | B17: Себестоимость | C17: Инвентаризационные расхождения | D17: 0.005 | E17: % food cost | F17: Допущение | G17: Рабочий резерв
A18: ALA_CHECK | B18: А-ля карт | C18: Средний чек на гостя | D18: 1000 | E18: руб./гость | F18: Подтверждено | G18: Пользователь
A19: ALA_MON_THU | B19: А-ля карт | C19: Гостей понедельник–четверг | D19: 32 | E19: гостей/день | F19: Подтверждено | G19: Пользователь
A20: ALA_FRI | B20: А-ля карт | C20: Гостей в пятницу | D20: 45 | E20: гостей/день | F20: Подтверждено | G20: Пользователь
A21: ALA_SAT | B21: А-ля карт | C21: Гостей в субботу | D21: 80 | E21: гостей/день | F21: Подтверждено | G21: Пользователь
... A27: LUNCH_DISCOUNT | B27: Бизнес-ланч | C27: Скидка к а-ля карт | D27: 0.25 | E27: % | F27: Подтверждено | G27: Пользователь, 17.07.2026; скидка 25% от среднего чека a-la carte
A28: LUNCH_CHECK | B28: Бизнес-ланч | C28: Средний чек после скидки | D28: =D18*(1-D27) | E28: руб./гость | F28: Расчёт | G28: Средний чек a-la carte × (1 − скидка) = 1 000 × 75% = 750 руб.
A29: LUNCH_COGS | B29: Бизнес-ланч | C29: Эффективный food cost | D29: =D24/(1-D27) | E29: % выручки | F29: Расчёт | G29: 30% / (1 − 25%)
A30: LUNCH_CASHLESS | B30: Бизнес-ланч | C30: Доля безналичной оплаты | D30: 1 | E30: % | F30: Допущение | G30: До уточнения — 100%
A31: DELIV_CHECK | B31: Доставка | C31: Средний чек | D31: 1200 | E31: руб./заказ | F31: Подтверждено | G31: Пользователь
A32: DELIV_WEEKDAY | B32: Доставка | C32: Заказов в будний день | D32: 15 | E32: заказов/день | F32: Подтверждено | G32: Пользователь
A33: DELIV_WEEKEND | B33: Доставка | C33: Заказов в субботу/воскресенье | D33: 30 | E33: заказов/день | F33: Подтверждено | G33: Пользователь
A34: DELIV_HOL | B34: Доставка | C34: Заказов в праздничный день | D34: 30 | E34: заказов/день | F34: Допущение | G34: Как выходной
A35: DELIV_COGS | B35: Доставка | C35: Food cost | D35: 0.3 | E35: % выручки | F35: Подтверждено | G35: Пользователь
A36: DELIV_COURIER | B36: Доставка | C36: Оплата доставщику | D36: 200 | E36: руб./заказ | F36: Подтверждено | G36: Пользователь
A37: DELIV_PACK | B37: Доставка | C37: Упаковка | D37: 65 | E37: руб./заказ | F37: Допущение | G37: Середина диапазона 50–80 руб.; заменить на факт
A38: DELIV_CASHLESS | B38: Доставка | C38: Доля безналичной оплаты | D38: 1 | E38: % | F38: Допущение | G38: До уточнения — 100%
A39: PICK_CHECK | B39: Самовывоз | C39: Средний чек | D39: 400 | E39: руб./заказ | F39: Подтверждено | G39: Пользователь
A40: PICK_ORDERS | B40: Самовывоз | C40: Заказов в календарный день | D40: 12 | E40: заказов/день | F40: Подтверждено | G40: Пользователь
A41: PICK_DISCOUNT | B41: Самовывоз | C41: Скидка к а-ля карт | D41: 0.3 | E41: % | F41: Подтверждено | G41: Пользователь
A42: PICK_COGS | B42: Самовывоз | C42: Эффективный food cost | D42: =D24/(1-D41) | E42: % выручки | F42: Расчёт | G42: 30% / (1 − 30%)
A43: PICK_PACK | B43: Самовывоз | C43: Упаковка | D43: 40 | E43: руб./заказ | F43: Допущение | G43: Середина диапазона 30–50 руб.; заменить на факт
A44: PICK_CASHLESS | B44: Самовывоз | C44: Доля безналичной оплаты | D44: 1 | E44: % | F44: Допущение | G44: До уточнения — 100%
A45: HOTEL_CHECK | B45: Гостиничный канал | C45: Средний чек | D45: 550 | E45: руб./заказ | F45: Подтверждено | G45: Пользователь; сумма с НДС
A46: HOTEL_ORDERS | B46: Гостиничный канал | C46: Заказов каждый календарный день | D46: 20 | E46: заказов/день | F46: Подтверждено | G46: Работает все 365 дней, включая банкеты
...

Sheet 02_КАЛЕНДАРЬ
A1: Календарь операционной модели: 01.09.2026–31.08.2027
A2: Банкеты: с ноября по 6 в месяц. В банкетный день завтраки, бизнес-ланч, доставка и самовывоз работают на 100%; а-ля карт — 20% до 17:00. Ужины гостиницы — 50% от завтраков ежедневно.
A4: Дата | B4: № месяца | C4: Месяц | D4: № дня недели | E4: День недели | F4: Праздник 1/0 | G4: Статус праздника | H4: Банкет 1/0 | I4: Категория банкета | J4: Кафе открыто | K4: Рабочий день | L4: Норма а-ля карт | M4: Гости а-ля карт | N4: Гости бизнес-ланча | O4: Норма доставки | P4: Заказы доставки | Q4: Самовывоз | R4: Завтраки гостиницы | S4: Банкеты | T4: Активные продажи кафе в банкет | U4: Ужины гостиницы
A5: 46266 | B5: 1 | C5: Сен-26 | D5: 2 | E5: Вт | F5: 0 | H5: 0 | J5: =1 | K5: =IF(AND(D5<=5,F5=0),1,0) | L5: =IF(F5=1,'01_ВВОД'!$D$23,CHOOSE(D5,'01_ВВОД'!$D$19,'01_ВВОД'!$D$19,'01_ВВОД'!$D$19,'01_ВВОД'!$D$19,'01_ВВОД'!$D$20,'01_ВВОД'!$D$21,'01_ВВОД'!$D$22)) | M5: =L5*IF(H5=1,'01_ВВОД'!$D$118,1) | N5: =IF(K5=1,'01_ВВОД'!$D$26,0) | O5: =IF(F5=1,'01_ВВОД'!$D$34,IF(D5<=5,'01_ВВОД'!$D$32,'01_ВВОД'!$D$33)) | P5: =O5 | Q5: ='01_ВВОД'!$D$40 | R5: ='01_ВВОД'!$D$46 | S5: =H5 | T5: =IF(H5=1,M5+N5+P5+Q5,0) | U5: =R5*'01_ВВОД'!$D$120
A6: 46267 | B6: 1 | C6: Сен-26 | D6: 3 | E6: Ср | F6: 0 | H6: 0 | J6: =1 | K6: =IF(AND(D6<=5,F6=0),1,0) | L6: =IF(F6=1,'01_ВВОД'!$D$23,CHOOSE(D6,'01_ВВОД'!$D$19,'01_ВВОД'!$D$19,'01_ВВОД'!$D$19,'01_ВВОД'!$D$19,'01_ВВОД'!$D$20,'01_ВВОД'!$D$21,'01_ВВОД'!$D$22)) | M6: =L6*IF(H6=1,'01_ВВОД'!$D$118,1) | N6: =IF(K6=1,'01_ВВОД'!$D$26,0) | O6: =IF(F6=1,'01_ВВОД'!$D$34,IF(D6<=5,'01_ВВОД'!$D$32,'01_ВВОД'!$D$33)) | P6: =O6 | Q6: ='01_ВВОД'!$D$40 | R6: ='01_ВВОД'!$D$46 | S6: =H6 | T6: =IF(H6=1,M6+N6+P6+Q6,0) | U6: =R6*'01_ВВОД'!$D$120
A7: 46268 | B7: 1 | C7: Сен-26 | D7: 4 | E7: Чт | F7: 0 | H7: 0 | J7: =1 | K7: =IF(AND(D7<=5,F7=0),1,0) | L7: =IF(F7=1,'01_ВВОД'!$D$23,CHOOSE(D7,'01_ВВОД'!$D$19,'01_ВВОД'!$D$19,'01_ВВОД'!$D$19,'01_ВВОД'!$D$19,'01_ВВОД'!$D$20,'01_ВВОД'!$D$21,'01_ВВОД'!$D$22)) | M7: =L7*IF(H7=1,'01_ВВОД'!$D$118,1) | N7: =IF(K7=1,'01_ВВОД'!$D$26,0) | O7: =IF(F7=1,'01_ВВОД'!$D$34,IF(D7<=5,'01_ВВОД'!$D$32,'01_ВВОД'!$D$33)) | P7: =O7 | Q7: ='01_ВВОД'!$D$40 | R7: ='01_ВВОД'!$D$46 | S7: =H7 | T7: =IF(H7=1,M7+N7+P7+Q7,0) | U7: =R7*'01_ВВОД'!$D$120
A8: 46269 | B8: 1 | C8: Сен-26 | D8: 5 | E8: Пт | F8: 0 | H8: 0 | J8: =1 | K8: =IF(AND(D8<=5,F8=0),1,0) | L8: =IF(F8=1,'01_ВВОД'!$D$23,CHOOSE(D8,'01_ВВОД'!$D$19,'01_ВВОД'!$D$19,'01_ВВОД'!$D$19,'01_ВВОД'!$D$19,'01_ВВОД'!$D$20,'01_ВВОД'!$D$21,'01_ВВОД'!$D$22)) | M8: =L8*IF(H8=1,'01_ВВОД'!$D$118,1) | N8: =IF(K8=1,'01_ВВОД'!$D$26,0) | O8: =IF(F8=1,'01_ВВОД'!$D$34,IF(D8<=5,'01_ВВОД'!$D$32,'01_ВВОД'!$D$33)) | P8: =O8 | Q8: ='01_ВВОД'!$D$40 | R8: ='01_ВВОД'!$D$46 | S8: =H8 | T8: =IF(H8=1,M8+N8+P8+Q8,0) | U8: =R8*'01_ВВОД'!$D$120
A9: 46270 | B9: 1 | C9: Сен-26 | D9: 6 | E9: Сб | F9: 0 | H9: 0 | J9: =1 | K9: =IF(AND(D9<=5,F9=0),1,0) | L9: =IF(F9=1,'01_ВВОД'!$D$23,CHOOSE(D9,'01_ВВОД'!$D$19,'01_ВВОД'!$D$19,'01_ВВОД'!$D$19,'01_ВВОД'!$D$19,'01_ВВОД'!$D$20,'01_ВВОД'!$D$21,'01_ВВОД'!$D$22)) | M9: =L9*IF(H9=1,'01_ВВОД'!$D$118,1) | N9: =IF(K9=1,'01_ВВОД'!$D$26,0) | O9: =IF(F9=1,'01_ВВОД'!$D$34,IF(D9<=5,'01_ВВОД'!$D$32,'01_ВВОД'!$D$33)) | P9: =O9 | Q9: ='01_ВВОД'!$D$40 | R9: ='01_ВВОД'!$D$46 | S9: =H9 | T9: =IF(H9=1,M9+N9+P9+Q9,0) | U9: =R9*'01_ВВОД'!$D$120
A10: 46271 | B10: 1 | C10: Сен-26 | D10: 7 | E10: Вс | F10: 0 | H10: 0 | J10: =1 | K10: =IF(AND(D10<=5,F10=0),1,0) | L10: =IF(F10=1,'01_ВВОД'!$D$23,CHOOSE(D10,'01_ВВОД'!$D$19,'01_ВВОД'!$D$19,'01_ВВОД'!$D$19,'01_ВВОД'!$D$19,'01_ВВОД'!$D$20,'01_ВВОД'!$D$21,'01_ВВОД'!$D$22)) | M10: =L10*IF(H10=1,'01_ВВОД'!$D$118,1) | N10: =IF(K10=1,'01_ВВОД'!$D$26,0) | O10: =IF(F10=1,'01_ВВОД'!$D$34,IF(D10<=5,'01_ВВОД'!$D$32,'01_ВВОД'!$D$33)) | P10: =O10 | Q10: ='01_ВВОД'!$D$40 | R10: ='01_ВВОД'!$D$46 | S10: =H10 | T10: =IF(H10=1,M10+N10+P10+Q10,0) | U10: =R10*'01_ВВОД'!$D$120
A11: 46272 | B11: 1 | C11: Сен-26 | D11: 1 | E11: Пн | F11: 0 | H11: 0 | J11: =1 | K11: =IF(AND(D11<=5,F11=0),1,0) | L11: =IF(F11=1,'01_ВВОД'!$D$23,CHOOSE(D11,'01_ВВОД'!$D$19,'01_ВВОД'!$D$19,'01_ВВОД'!$D$19,'01_ВВОД'!$D$19,'01_ВВОД'!$D$20,'01_ВВОД'!$D$21,'01_ВВОД'!$D$22)) | M11: =L11*IF(H11=1,'01_ВВОД'!$D$118,1) | N11: =IF(K11=1,'01_ВВОД'!$D$26,0) | O11: =IF(F11=1,'01_ВВОД'!$D$34,IF(D11<=5,'01_ВВОД'!$D$32,'01_ВВОД'!$D$33)) | P11: =O11 | Q11: ='01_ВВОД'!$D$40 | R11: ='01_ВВОД'!$D$46 | S11: =H11 | T11: =IF(H11=1,M11+N11+P11+Q11,0) | U11: =R11*'01_ВВОД'!$D$120
A12: 46273 | B12: 1 | C12: Сен-26 | D12: 2 | E12: Вт | F12: 0 | H12: 0 | J12: =1 | K12: =IF(AND(D12<=5,F12=0),1,0) | L12: =IF(F12=1,'01_ВВОД'!$D$23,CHOOSE(D12,'01_ВВОД'!$D$19,'01_ВВОД'!$D$19,'01_ВВОД'!$D$19,'01_ВВОД'!$D$19,'01_ВВОД'!$D$20,'01_ВВОД'!$D$21,'01_ВВОД'!$D$22)) | M12: =L12*IF(H12=1,'01_ВВОД'!$D$118,1) | N12: =IF(K12=1,'01_ВВОД'!$D$26,0) | O12: =IF(F12=1,'01_ВВОД'!$D$34,IF(D12<=5,'01_ВВОД'!$D$32,'01_ВВОД'!$D$33)) | P12: =O12 | Q12: ='01_ВВОД'!$D$40 | R12: ='01_ВВОД'!$D$46 | S12: =H12 | T12: =IF(H12=1,M12+N12+P12+Q12,0) | U12: =R12*'01_ВВОД'!$D$120
A13: 46274 | B13: 1 | C13: Сен-26 | D13: 3 | E13: Ср | F13: 0 | H13: 0 | J13: =1 | K13: =IF(AND(D13<=5,F13=0),1,0) | L13: =IF(F13=1,'01_ВВОД'!$D$23,CHOOSE(D13,'01_ВВОД'!$D$19,'01_ВВОД'!$D$19,'01_ВВОД'!$D$19,'01_ВВОД'!$D$19,'01_ВВОД'!$D$20,'01_ВВОД'!$D$21,'01_ВВОД'!$D$22)) | M13: =L13*IF(H13=1,'01_ВВОД'!$D$118,1) | N13: =IF(K13=1,'01_ВВОД'!$D$26,0) | O13: =IF(F13=1,'01_ВВОД'!$D$34,IF(D13<=5,'01_ВВОД'!$D$32,'01_ВВОД'!$D$33)) | P13: =O13 | Q13: ='01_ВВОД'!$D$40 | R13: ='01_ВВОД'!$D$46 | S13: =H13 | T13: =IF(H13=1,M13+N13+P13+Q13,0) | U13: =R13*'01_ВВОД'!$D$120
A14: 46275 | B14: 1 | C14: Сен-26 | D14: 4 | E14: Чт | F14: 0 | H14: 0 | J14: =1 | K14: =IF(AND(D14<=5,F14=0),1,0) | L14: =IF(F14=1,'01_ВВОД'!$D$23,CHOOSE(D14,'01_ВВОД'!$D$19,'01_ВВОД'!$D$19,'01_ВВОД'!$D$19,'01_ВВОД'!$D$19,'01_ВВОД'!$D$20,'01_ВВОД'!$D$21,'01_ВВОД'!$D$22)) | M14: =L14*IF(H14=1,'01_ВВОД'!$D$118,1) | N14: =IF(K14=1,'01_ВВОД'!$D$26,0) | O14: =IF(F14=1,'01_ВВОД'!$D$34,IF(D14<=5,'01_ВВОД'!$D$32,'01_ВВОД'!$D$33)) | P14: =O14 | Q14: ='01_ВВОД'!$D$40 | R14: ='01_ВВОД'!$D$46 | S14: =H14 | T14: =IF(H14=1,M14+N14+P14+Q14,0) | U14: =R14*'01_ВВОД'!$D$120
A15: 46276 | B15: 1 | C15: Сен-26 | D15: 5 | E15: Пт | F15: 0 | H15: 0 | J15: =1 | K15: =IF(AND(D15<=5,F15=0),1,0) | L15: =IF(F15=1,'01_ВВОД'!$D$23,CHOOSE(D15,'01_ВВОД'!$D$19,'01_ВВОД'!$D$19,'01_ВВОД'!$D$19,'01_ВВОД'!$D$19,'01_ВВОД'!$D$20,'01_ВВОД'!$D$21,'01_ВВОД'!$D$22)) | M15: =L15*IF(H15=1,'01_ВВОД'!$D$118,1) | N15: =IF(K15=1,'01_ВВОД'!$D$26,0) | O15: =IF(F15=1,'01_ВВОД'!$D$34,IF(D15<=5,'01_ВВОД'!$D$32,'01_ВВОД'!$D$33)) | P15: =O15 | Q15: ='01_ВВОД'!$D$40 | R15: ='01_ВВОД'!$D$46 | S15: =H15 | T15: =IF(H15=1,M15+N15+P15+Q15,0) | U15: =R15*'01_ВВОД'!$D$120
A16: 46277 | B16: 1 | C16: Сен-26 | D16: 6 | E16: Сб | F16: 0 | H16: 0 | J16: =1 | K16: =IF(AND(D16<=5,F16=0),1,0) | L16: =IF(F16=1,'01_ВВОД'!$D$23,CHOOSE(D16,'01_ВВОД'!$D$19,'01_ВВОД'!$D$19,'01_ВВОД'!$D$19,'01_ВВОД'!$D$19,'01_ВВОД'!$D$20,'01_ВВОД'!$D$21,'01_ВВОД'!$D$22)) | M16: =L16*IF(H16=1,'01_ВВОД'!$D$118,1) | N16: =IF(K16=1,'01_ВВОД'!$D$26,0) | O16: =IF(F16=1,'01_ВВОД'!$D$34,IF(D16<=5,'01_ВВОД'!$D$32,'01_ВВОД'!$D$33)) | P16: =O16 | Q16: ='01_ВВОД'!$D$40 | R16: ='01_ВВОД'!$D$46 | S16: =H16 | T16: =IF(H16=1,M16+N16+P16+Q16,0) | U16: =R16*'01_ВВОД'!$D$120
... A68: 46329 | B68: 3 | C68: Ноя-26 | D68: 2 | E68: Вт | F68: 0 | H68: 0 | J68: =1 | K68: =IF(AND(D68<=5,F68=0),1,0) | L68: =IF(F68=1,'01_ВВОД'!$D$23,CHOOSE(D68,'01_ВВОД'!$D$19,'01_ВВОД'!$D$19,'01_ВВОД'!$D$19,'01_ВВОД'!$D$19,'01_ВВОД'!$D$20,'01_ВВОД'!$D$21,'01_ВВОД'!$D$22)) | M68: =L68*IF(H68=1,'01_ВВОД'!$D$118,1) | N68: =IF(K68=1,'01_ВВОД'!$D$26,0) | O68: =IF(F68=1,'01_ВВОД'!$D$34,IF(D68<=5,'01_ВВОД'!$D$32,'01_ВВОД'!$D$33)) | P68: =O68 | Q68: ='01_ВВОД'!$D$40 | R68: ='01_ВВОД'!$D$46 | S68: =H68 | T68: =IF(H68=1,M68+N68+P68+Q68,0) | U68: =R68*'01_ВВОД'!$D$120
A69: 46330 | B69: 3 | C69: Ноя-26 | D69: 3 | E69: Ср | F69: 1 | G69: Подтверждено для 2026 | H69: 0 | J69: =1 | K69: =IF(AND(D69<=5,F69=0),1,0) | L69: =IF(F69=1,'01_ВВОД'!$D$23,CHOOSE(D69,'01_ВВОД'!$D$19,'01_ВВОД'!$D$19,'01_ВВОД'!$D$19,'01_ВВОД'!$D$19,'01_ВВОД'!$D$20,'01_ВВОД'!$D$21,'01_ВВОД'!$D$22)) | M69: =L69*IF(H69=1,'01_ВВОД'!$D$118,1) | N69: =IF(K69=1,'01_ВВОД'!$D$26,0) | O69: =IF(F69=1,'01_ВВОД'!$D$34,IF(D69<=5,'01_ВВОД'!$D$32,'01_ВВОД'!$D$33)) | P69: =O69 | Q69: ='01_ВВОД'!$D$40 | R69: ='01_ВВОД'!$D$46 | S69: =H69 | T69: =IF(H69=1,M69+N69+P69+Q69,0) | U69: =R69*'01_ВВОД'!$D$120
A70: 46331 | B70: 3 | C70: Ноя-26 | D70: 4 | E70: Чт | F70: 0 | H70: 0 | J70: =1 | K70: =IF(AND(D70<=5,F70=0),1,0) | L70: =IF(F70=1,'01_ВВОД'!$D$23,CHOOSE(D70,'01_ВВОД'!$D$19,'01_ВВОД'!$D$19,'01_ВВОД'!$D$19,'01_ВВОД'!$D$19,'01_ВВОД'!$D$20,'01_ВВОД'!$D$21,'01_ВВОД'!$D$22)) | M70: =L70*IF(H70=1,'01_ВВОД'!$D$118,1) | N70: =IF(K70=1,'01_ВВОД'!$D$26,0) | O70: =IF(F70=1,'01_ВВОД'!$D$34,IF(D70<=5,'01_ВВОД'!$D$32,'01_ВВОД'!$D$33)) | P70: =O70 | Q70: ='01_ВВОД'!$D$40 | R70: ='01_ВВОД'!$D$46 | S70: =H70 | T70: =IF(H70=1,M70+N70+P70+Q70,0) | U70: =R70*'01_ВВОД'!$D$120
A71: 46332 | B71: 3 | C71: Ноя-26 | D71: 5 | E71: Пт | F71: 0 | H71: 0 | J71: =1 | K71: =IF(AND(D71<=5,F71=0),1,0) | L71: =IF(F71=1,'01_ВВОД'!$D$23,CHOOSE(D71,'01_ВВОД'!$D$19,'01_ВВОД'!$D$19,'01_ВВОД'!$D$19,'01_ВВОД'!$D$19,'01_ВВОД'!$D$20,'01_ВВОД'!$D$21,'01_ВВОД'!$D$22)) | M71: =L71*IF(H71=1,'01_ВВОД'!$D$118,1) | N71: =IF(K71=1,'01_ВВОД'!$D$26,0) | O71: =IF(F71=1,'01_ВВОД'!$D$34,IF(D71<=5,'01_ВВОД'!$D$32,'01_ВВОД'!$D$33)) | P71: =O71 | Q71: ='01_ВВОД'!$D$40 | R71: ='01_ВВОД'!$D$46 | S71: =H71 | T71: =IF(H71=1,M71+N71+P71+Q71,0) | U71: =R71*'01_ВВОД'!$D$120
A72: 46333 | B72: 3 | C72: Ноя-26 | D72: 6 | E72: Сб | F72: 0 | H72: 1 | I72: Пт–Вс | J72: =1 | K72: =IF(AND(D72<=5,F72=0),1,0) | L72: =IF(F72=1,'01_ВВОД'!$D$23,CHOOSE(D72,'01_ВВОД'!$D$19,'01_ВВОД'!$D$19,'01_ВВОД'!$D$19,'01_ВВОД'!$D$19,'01_ВВОД'!$D$20,'01_ВВОД'!$D$21,'01_ВВОД'!$D$22)) | M72: =L72*IF(H72=1,'01_ВВОД'!$D$118,1) | N72: =IF(K72=1,'01_ВВОД'!$D$26,0) | O72: =IF(F72=1,'01_ВВОД'!$D$34,IF(D72<=5,'01_ВВОД'!$D$32,'01_ВВОД'!$D$33)) | P72: =O72 | Q72: ='01_ВВОД'!$D$40 | R72: ='01_ВВОД'!$D$46 | S72: =H72 | T72: =IF(H72=1,M72+N72+P72+Q72,0) | U72: =R72*'01_ВВОД'!$D$120
A73: 46334 | B73: 3 | C73: Ноя-26 | D73: 7 | E73: Вс | F73: 0 | H73: 0 | J73: =1 | K73: =IF(AND(D73<=5,F73=0),1,0) | L73: =IF(F73=1,'01_ВВОД'!$D$23,CHOOSE(D73,'01_ВВОД'!$D$19,'01_ВВОД'!$D$19,'01_ВВОД'!$D$19,'01_ВВОД'!$D$19,'01_ВВОД'!$D$20,'01_ВВОД'!$D$21,'01_ВВОД'!$D$22)) | M73: =L73*IF(H73=1,'01_ВВОД'!$D$118,1) | N73: =IF(K73=1,'01_ВВОД'!$D$26,0) | O73: =IF(F73=1,'01_ВВОД'!$D$34,IF(D73<=5,'01_ВВОД'!$D$32,'01_ВВОД'!$D$33)) | P73: =O73 | Q73: ='01_ВВОД'!$D$40 | R73: ='01_ВВОД'!$D$46 | S73: =H73 | T73: =IF(H73=1,M73+N73+P73+Q73,0) | U73: =R73*'01_ВВОД'!$D$120
A74: 46335 | B74: 3 | C74: Ноя-26 | D74: 1 | E74: Пн | F74: 0 | H74: 0 | J74: =1 | K74: =IF(AND(D74<=5,F74=0),1,0) | L74: =IF(F74=1,'01_ВВОД'!$D$23,CHOOSE(D74,'01_ВВОД'!$D$19,'01_ВВОД'!$D$19,'01_ВВОД'!$D$19,'01_ВВОД'!$D$19,'01_ВВОД'!$D$20,'01_ВВОД'!$D$21,'01_ВВОД'!$D$22)) | M74: =L74*IF(H74=1,'01_ВВОД'!$D$118,1) | N74: =IF(K74=1,'01_ВВОД'!$D$26,0) | O74: =IF(F74=1,'01_ВВОД'!$D$34,IF(D74<=5,'01_ВВОД'!$D$32,'01_ВВОД'!$D$33)) | P74: =O74 | Q74: ='01_ВВОД'!$D$40 | R74: ='01_ВВОД'!$D$46 | S74: =H74 | T74: =IF(H74=1,M74+N74+P74+Q74,0) | U74: =R74*'01_ВВОД'!$D$120
A75: 46336 | B75: 3 | C75: Ноя-26 | D75: 2 | E75: Вт | F75: 0 | H75: 0 | J75: =1 | K75: =IF(AND(D75<=5,F75=0),1,0) | L75: =IF(F75=1,'01_ВВОД'!$D$23,CHOOSE(D75,'01_ВВОД'!$D$19,'01_ВВОД'!$D$19,'01_ВВОД'!$D$19,'01_ВВОД'!$D$19,'01_ВВОД'!$D$20,'01_ВВОД'!$D$21,'01_ВВОД'!$D$22)) | M75: =L75*IF(H75=1,'01_ВВОД'!$D$118,1) | N75: =IF(K75=1,'01_ВВОД'!$D$26,0) | O75: =IF(F75=1,'01_ВВОД'!$D$34,IF(D75<=5,'01_ВВОД'!$D$32,'01_ВВОД'!$D$33)) | P75: =O75 | Q75: ='01_ВВОД'!$D$40 | R75: ='01_ВВОД'!$D$46 | S75: =H75 | T75: =IF(H75=1,M75+N75+P75+Q75,0) | U75: =R75*'01_ВВОД'!$D$120
A76: 46337 | B76: 3 | C76: Ноя-26 | D76: 3 | E76: Ср | F76: 0 | H76: 0 | J76: =1 | K76: =IF(AND(D76<=5,F76=0),1,0) | L76: =IF(F76=1,'01_ВВОД'!$D$23,CHOOSE(D76,'01_ВВОД'!$D$19,'01_ВВОД'!$D$19,'01_ВВОД'!$D$19,'01_ВВОД'!$D$19,'01_ВВОД'!$D$20,'01_ВВОД'!$D$21,'01_ВВОД'!$D$22)) | M76: =L76*IF(H76=1,'01_ВВОД'!$D$118,1) | N76: =IF(K76=1,'01_ВВОД'!$D$26,0) | O76: =IF(F76=1,'01_ВВОД'!$D$34,IF(D76<=5,'01_ВВОД'!$D$32,'01_ВВОД'!$D$33)) | P76: =O76 | Q76: ='01_ВВОД'!$D$40 | R76: ='01_ВВОД'!$D$46 | S76: =H76 | T76: =IF(H76=1,M76+N76+P76+Q76,0) | U76: =R76*'01_ВВОД'!$D$120
A77: 46338 | B77: 3 | C77: Ноя-26 | D77: 4 | E77: Чт | F77: 0 | H77: 0 | J77: =1 | K77: =IF(AND(D77<=5,F77=0),1,0) | L77: =IF(F77=1,'01_ВВОД'!$D$23,CHOOSE(D77,'01_ВВОД'!$D$19,'01_ВВОД'!$D$19,'01_ВВОД'!$D$19,'01_ВВОД'!$D$19,'01_ВВОД'!$D$20,'01_ВВОД'!$D$21,'01_ВВОД'!$D$22)) | M77: =L77*IF(H77=1,'01_ВВОД'!$D$118,1) | N77: =IF(K77=1,'01_ВВОД'!$D$26,0) | O77: =IF(F77=1,'01_ВВОД'!$D$34,IF(D77<=5,'01_ВВОД'!$D$32,'01_ВВОД'!$D$33)) | P77: =O77 | Q77: ='01_ВВОД'!$D$40 | R77: ='01_ВВОД'!$D$46 | S77: =H77 | T77: =IF(H77=1,M77+N77+P77+Q77,0) | U77: =R77*'01_ВВОД'!$D$120
A78: 46339 | B78: 3 | C78: Ноя-26 | D78: 5 | E78: Пт | F78: 0 | H78: 1 | I78: Пт–Вс | J78: =1 | K78: =IF(AND(D78<=5,F78=0),1,0) | L78: =IF(F78=1,'01_ВВОД'!$D$23,CHOOSE(D78,'01_ВВОД'!$D$19,'01_ВВОД'!$D$19,'01_ВВОД'!$D$19,'01_ВВОД'!$D$19,'01_ВВОД'!$D$20,'01_ВВОД'!$D$21,'01_ВВОД'!$D$22)) | M78: =L78*IF(H78=1,'01_ВВОД'!$D$118,1) | N78: =IF(K78=1,'01_ВВОД'!$D$26,0) | O78: =IF(F78=1,'01_ВВОД'!$D$34,IF(D78<=5,'01_ВВОД'!$D$32,'01_ВВОД'!$D$33)) | P78: =O78 | Q78: ='01_ВВОД'!$D$40 | R78: ='01_ВВОД'!$D$46 | S78: =H78 | T78: =IF(H78=1,M78+N78+P78+Q78,0) | U78: =R78*'01_ВВОД'!$D$120
A79: 46340 | B79: 3 | C79: Ноя-26 | D79: 6 | E79: Сб | F79: 0 | H79: 0 | J79: =1 | K79: =IF(AND(D79<=5,F79=0),1,0) | L79: =IF(F79=1,'01_ВВОД'!$D$23,CHOOSE(D79,'01_ВВОД'!$D$19,'01_ВВОД'!$D$19,'01_ВВОД'!$D$19,'01_ВВОД'!$D$19,'01_ВВОД'!$D$20,'01_ВВОД'!$D$21,'01_ВВОД'!$D$22)) | M79: =L79*IF(H79=1,'01_ВВОД'!$D$118,1) | N79: =IF(K79=1,'01_ВВОД'!$D$26,0) | O79: =IF(F79=1,'01_ВВОД'!$D$34,IF(D79<=5,'01_ВВОД'!$D$32,'01_ВВОД'!$D$33)) | P79: =O79 | Q79: ='01_ВВОД'!$D$40 | R79: ='01_ВВОД'!$D$46 | S79: =H79 | T79: =IF(H79=1,M79+N79+P79+Q79,0) | U79: =R79*'01_ВВОД'!$D$120
A80: 46341 | B80: 3 | C80: Ноя-26 | D80: 7 | E80: Вс | F80: 0 | H80: 1 | I80: Пт–Вс | J80: =1 | K80: =IF(AND(D80<=5,F80=0),1,0) | L80: =IF(F80=1,'01_ВВОД'!$D$23,CHOOSE(D80,'01_ВВОД'!$D$19,'01_ВВОД'!$D$19,'01_ВВОД'!$D$19,'01_ВВОД'!$D$19,'01_ВВОД'!$D$20,'01_ВВОД'!$D$21,'01_ВВОД'!$D$22)) | M80: =L80*IF(H80=1,'01_ВВОД'!$D$118,1) | N80: =IF(K80=1,'01_ВВОД'!$D$26,0) | O80: =IF(F80=1,'01_ВВОД'!$D$34,IF(D80<=5,'01_ВВОД'!$D$32,'01_ВВОД'!$D$33)) | P80: =O80 | Q80: ='01_ВВОД'!$D$40 | R80: ='01_ВВОД'!$D$46 | S80: =H80 | T80: =IF(H80=1,M80+N80+P80+Q80,0) | U80: =R80*'01_ВВОД'!$D$120
A81: 46342 | B81: 3 | C81: Ноя-26 | D81: 1 | E81: Пн | F81: 0 | H81: 1 | I81: Пн–Чт | J81: =1 | K81: =IF(AND(D81<=5,F81=0),1,0) | L81: =IF(F81=1,'01_ВВОД'!$D$23,CHOOSE(D81,'01_ВВОД'!$D$19,'01_ВВОД'!$D$19,'01_ВВОД'!$D$19,'01_ВВОД'!$D$19,'01_ВВОД'!$D$20,'01_ВВОД'!$D$21,'01_ВВОД'!$D$22)) | M81: =L81*IF(H81=1,'01_ВВОД'!$D$118,1) | N81: =IF(K81=1,'01_ВВОД'!$D$26,0) | O81: =IF(F81=1,'01_ВВОД'!$D$34,IF(D81<=5,'01_ВВОД'!$D$32,'01_ВВОД'!$D$33)) | P81: =O81 | Q81: ='01_ВВОД'!$D$40 | R81: ='01_ВВОД'!$D$46 | S81: =H81 | T81: =IF(H81=1,M81+N81+P81+Q81,0) | U81: =R81*'01_ВВОД'!$D$120
A82: 46343 | B82: 3 | C82: Ноя-26 | D82: 2 | E82: Вт | F82: 0 | H82: 0 | J82: =1 | K82: =IF(AND(D82<=5,F82=0),1,0) | L82: =IF(F82=1,'01_ВВОД'!$D$23,CHOOSE(D82,'01_ВВОД'!$D$19,'01_ВВОД'!$D$19,'01_ВВОД'!$D$19,'01_ВВОД'!$D$19,'01_ВВОД'!$D$20,'01_ВВОД'!$D$21,'01_ВВОД'!$D$22)) | M82: =L82*IF(H82=1,'01_ВВОД'!$D$118,1) | N82: =IF(K82=1,'01_ВВОД'!$D$26,0) | O82: =IF(F82=1,'01_ВВОД'!$D$34,IF(D82<=5,'01_ВВОД'!$D$32,'01_ВВОД'!$D$33)) | P82: =O82 | Q82: ='01_ВВОД'!$D$40 | R82: ='01_ВВОД'!$D$46 | S82: =H82 | T82: =IF(H82=1,M82+N82+P82+Q82,0) | U82: =R82*'01_ВВОД'!$D$120
A83: 46344 | B83: 3 | C83: Ноя-26 | D83: 3 | E83: Ср | F83: 0 | H83: 0 | J83: =1 | K83: =IF(AND(D83<=5,F83=0),1,0) | L83: =IF(F83=1,'01_ВВОД'!$D$23,CHOOSE(D83,'01_ВВОД'!$D$19,'01_ВВОД'!$D$19,'01_ВВОД'!$D$19,'01_ВВОД'!$D$19,'01_ВВОД'!$D$20,'01_ВВОД'!$D$21,'01_ВВОД'!$D$22)) | M83: =L83*IF(H83=1,'01_ВВОД'!$D$118,1) | N83: =IF(K83=1,'01_ВВОД'!$D$26,0) | O83: =IF(F83=1,'01_ВВОД'!$D$34,IF(D83<=5,'01_ВВОД'!$D$32,'01_ВВОД'!$D$33)) | P83: =O83 | Q83: ='01_ВВОД'!$D$40 | R83: ='01_ВВОД'!$D$46 | S83: =H83 | T83: =IF(H83=1,M83+N83+P83+Q83,0) | U83: =R83*'01_ВВОД'!$D$120
A84: 46345 | B84: 3 | C84: Ноя-26 | D84: 4 | E84: Чт | F84: 0 | H84: 0 | J84: =1 | K84: =IF(AND(D84<=5,F84=0),1,0) | L84: =IF(F84=1,'01_ВВОД'!$D$23,CHOOSE(D84,'01_ВВОД'!$D$19,'01_ВВОД'!$D$19,'01_ВВОД'!$D$19,'01_ВВОД'!$D$19,'01_ВВОД'!$D$20,'01_ВВОД'!$D$21,'01_ВВОД'!$D$22)) | M84: =L84*IF(H84=1,'01_ВВОД'!$D$118,1) | N84: =IF(K84=1,'01_ВВОД'!$D$26,0) | O84: =IF(F84=1,'01_ВВОД'!$D$34,IF(D84<=5,'01_ВВОД'!$D$32,'01_ВВОД'!$D$33)) | P84: =O84 | Q84: ='01_ВВОД'!$D$40 | R84: ='01_ВВОД'!$D$46 | S84: =H84 | T84: =IF(H84=1,M84+N84+P84+Q84,0) | U84: =R84*'01_ВВОД'!$D$120
A85: 46346 | B85: 3 | C85: Ноя-26 | D85: 5 | E85: Пт | F85: 0 | H85: 1 | I85: Пт–Вс | J85: =1 | K85: =IF(AND(D85<=5,F85=0),1,0) | L85: =IF(F85=1,'01_ВВОД'!$D$23,CHOOSE(D85,'01_ВВОД'!$D$19,'01_ВВОД'!$D$19,'01_ВВОД'!$D$19,'01_ВВОД'!$D$19,'01_ВВОД'!$D$20,'01_ВВОД'!$D$21,'01_ВВОД'!$D$22)) | M85: =L85*IF(H85=1,'01_ВВОД'!$D$118,1) | N85: =IF(K85=1,'01_ВВОД'!$D$26,0) | O85: =IF(F85=1,'01_ВВОД'!$D$34,IF(D85<=5,'01_ВВОД'!$D$32,'01_ВВОД'!$D$33)) | P85: =O85 | Q85: ='01_ВВОД'!$D$40 | R85: ='01_ВВОД'!$D$46 | S85: =H85 | T85: =IF(H85=1,M85+N85+P85+Q85,0) | U85: =R85*'01_ВВОД'!$D$120
A86: 46347 | B86: 3 | C86: Ноя-26 | D86: 6 | E86: Сб | F86: 0 | H86: 0 | J86: =1 | K86: =IF(AND(D86<=5,F86=0),1,0) | L86: =IF(F86=1,'01_ВВОД'!$D$23,CHOOSE(D86,'01_ВВОД'!$D$19,'01_ВВОД'!$D$19,'01_ВВОД'!$D$19,'01_ВВОД'!$D$19,'01_ВВОД'!$D$20,'01_ВВОД'!$D$21,'01_ВВОД'!$D$22)) | M86: =L86*IF(H86=1,'01_ВВОД'!$D$118,1) | N86: =IF(K86=1,'01_ВВОД'!$D$26,0) | O86: =IF(F86=1,'01_ВВОД'!$D$34,IF(D86<=5,'01_ВВОД'!$D$32,'01_ВВОД'!$D$33)) | P86: =O86 | Q86: ='01_ВВОД'!$D$40 | R86: ='01_ВВОД'!$D$46 | S86: =H86 | T86: =IF(H86=1,M86+N86+P86+Q86,0) | U86: =R86*'01_ВВОД'!$D$120
A87: 46348 | B87: 3 | C87: Ноя-26 | D87: 7 | E87: Вс | F87: 0 | H87: 0 | J87: =1 | K87: =IF(AND(D87<=5,F87=0),1,0) | L87: =IF(F87=1,'01_ВВОД'!$D$23,CHOOSE(D87,'01_ВВОД'!$D$19,'01_ВВОД'!$D$19,'01_ВВОД'!$D$19,'01_ВВОД'!$D$19,'01_ВВОД'!$D$20,'01_ВВОД'!$D$21,'01_ВВОД'!$D$22)) | M87: =L87*IF(H87=1,'01_ВВОД'!$D$118,1) | N87: =IF(K87=1,'01_ВВОД'!$D$26,0) | O87: =IF(F87=1,'01_ВВОД'!$D$34,IF(D87<=5,'01_ВВОД'!$D$32,'01_ВВОД'!$D$33)) | P87: =O87 | Q87: ='01_ВВОД'!$D$40 | R87: ='01_ВВОД'!$D$46 | S87: =H87 | T87: =IF(H87=1,M87+N87+P87+Q87,0) | U87: =R87*'01_ВВОД'!$D$120
A88: 46349 | B88: 3 | C88: Ноя-26 | D88: 1 | E88: Пн | F88: 0 | H88: 0 | J88: =1 | K88: =IF(AND(D88<=5,F88=0),1,0) | L88: =IF(F88=1,'01_ВВОД'!$D$23,CHOOSE(D88,'01_ВВОД'!$D$19,'01_ВВОД'!$D$19,'01_ВВОД'!$D$19,'01_ВВОД'!$D$19,'01_ВВОД'!$D$20,'01_ВВОД'!$D$21,'01_ВВОД'!$D$22)) | M88: =L88*IF(H88=1,'01_ВВОД'!$D$118,1) | N88: =IF(K88=1,'01_ВВОД'!$D$26,0) | O88: =IF(F88=1,'01_ВВОД'!$D$34,IF(D88<=5,'01_ВВОД'!$D$32,'01_ВВОД'!$D$33)) | P88: =O88 | Q88: ='01_ВВОД'!$D$40 | R88: ='01_ВВОД'!$D$46 | S88: =H88 | T88: =IF(H88=1,M88+N88+P88+Q88,0) | U88: =R88*'01_ВВОД'!$D$120
A89: 46350 | B89: 3 | C89: Ноя-26 | D89: 2 | E89: Вт | F89: 0 | H89: 0 | J89: =1 | K89: =IF(AND(D89<=5,F89=0),1,0) | L89: =IF(F89=1,'01_ВВОД'!$D$23,CHOOSE(D89,'01_ВВОД'!$D$19,'01_ВВОД'!$D$19,'01_ВВОД'!$D$19,'01_ВВОД'!$D$19,'01_ВВОД'!$D$20,'01_ВВОД'!$D$21,'01_ВВОД'!$D$22)) | M89: =L89*IF(H89=1,'01_ВВОД'!$D$118,1) | N89: =IF(K89=1,'01_ВВОД'!$D$26,0) | O89: =IF(F89=1,'01_ВВОД'!$D$34,IF(D89<=5,'01_ВВОД'!$D$32,'01_ВВОД'!$D$33)) | P89: =O89 | Q89: ='01_ВВОД'!$D$40 | R89: ='01_ВВОД'!$D$46 | S89: =H89 | T89: =IF(H89=1,M89+N89+P89+Q89,0) | U89: =R89*'01_ВВОД'!$D$120
A90: 46351 | B90: 3 | C90: Ноя-26 | D90: 3 | E90: Ср | F90: 0 | H90: 0 | J90: =1 | K90: =IF(AND(D90<=5,F90=0),1,0) | L90: =IF(F90=1,'01_ВВОД'!$D$23,CHOOSE(D90,'01_ВВОД'!$D$19,'01_ВВОД'!$D$19,'01_ВВОД'!$D$19,'01_ВВОД'!$D$19,'01_ВВОД'!$D$20,'01_ВВОД'!$D$21,'01_ВВОД'!$D$22)) | M90: =L90*IF(H90=1,'01_ВВОД'!$D$118,1) | N90: =IF(K90=1,'01_ВВОД'!$D$26,0) | O90: =IF(F90=1,'01_ВВОД'!$D$34,IF(D90<=5,'01_ВВОД'!$D$32,'01_ВВОД'!$D$33)) | P90: =O90 | Q90: ='01_ВВОД'!$D$40 | R90: ='01_ВВОД'!$D$46 | S90: =H90 | T90: =IF(H90=1,M90+N90+P90+Q90,0) | U90: =R90*'01_ВВОД'!$D$120
A91: 46352 | B91: 3 | C91: Ноя-26 | D91: 4 | E91: Чт | F91: 0 | H91: 0 | J91: =1 | K91: =IF(AND(D91<=5,F91=0),1,0) | L91: =IF(F91=1,'01_ВВОД'!$D$23,CHOOSE(D91,'01_ВВОД'!$D$19,'01_ВВОД'!$D$19,'01_ВВОД'!$D$19,'01_ВВОД'!$D$19,'01_ВВОД'!$D$20,'01_ВВОД'!$D$21,'01_ВВОД'!$D$22)) | M91: =L91*IF(H91=1,'01_ВВОД'!$D$118,1) | N91: =IF(K91=1,'01_ВВОД'!$D$26,0) | O91: =IF(F91=1,'01_ВВОД'!$D$34,IF(D91<=5,'01_ВВОД'!$D$32,'01_ВВОД'!$D$33)) | P91: =O91 | Q91: ='01_ВВОД'!$D$40 | R91: ='01_ВВОД'!$D$46 | S91: =H91 | T91: =IF(H91=1,M91+N91+P91+Q91,0) | U91: =R91*'01_ВВОД'!$D$120
A92: 46353 | B92: 3 | C92: Ноя-26 | D92: 5 | E92: Пт | F92: 0 | H92: 0 | J92: =1 | K92: =IF(AND(D92<=5,F92=0),1,0) | L92: =IF(F92=1,'01_ВВОД'!$D$23,CHOOSE(D92,'01_ВВОД'!$D$19,'01_ВВОД'!$D$19,'01_ВВОД'!$D$19,'01_ВВОД'!$D$19,'01_ВВОД'!$D$20,'01_ВВОД'!$D$21,'01_ВВОД'!$D$22)) | M92: =L92*IF(H92=1,'01_ВВОД'!$D$118,1) | N92: =IF(K92=1,'01_ВВОД'!$D$26,0) | O92: =IF(F92=1,'01_ВВОД'!$D$34,IF(D92<=5,'01_ВВОД'!$D$32,'01_ВВОД'!$D$33)) | P92: =O92 | Q92: ='01_ВВОД'!$D$40 | R92: ='01_ВВОД'!$D$46 | S92: =H92 | T92: =IF(H92=1,M92+N92+P92+Q92,0) | U92: =R92*'01_ВВОД'!$D$120
...

Sheet 03_ДОХОДЫ
A1: Доходы по направлениям
A2: Сценарий S03 наследует бизнес-ланч S02. Чек ужина — 1 000 руб.; food cost ужина равен food cost a-la carte; пересмотрены OPEX-inputs.
D3: 1 | E3: 2 | F3: 3 | G3: 4 | H3: 5 | I3: 6 | J3: 7 | K3: 8 | L3: 9 | M3: 10 | N3: 11 | O3: 12
A4: Код | B4: Раздел | C4: Показатель | D4: Сен-26 | E4: Окт-26 | F4: Ноя-26 | G4: Дек-26 | H4: Янв-27 | I4: Фев-27 | J4: Мар-27 | K4: Апр-27 | L4: Май-27 | M4: Июн-27 | N4: Июл-27 | O4: Авг-27 | P4: Итого за год | Q4: Среднее за месяц | R4: Ед.
A5: БИЗНЕС 1 — КАФЕ
A6: REV.ALA.QTY | B6: Кафе — а-ля карт | C6: Гости а-ля карт | D6: =SUMIF('02_КАЛЕНДАРЬ'!$B$5:$B$369,D$3,'02_КАЛЕНДАРЬ'!$M$5:$M$369) | E6: =SUMIF('02_КАЛЕНДАРЬ'!$B$5:$B$369,E$3,'02_КАЛЕНДАРЬ'!$M$5:$M$369) | F6: =SUMIF('02_КАЛЕНДАРЬ'!$B$5:$B$369,F$3,'02_КАЛЕНДАРЬ'!$M$5:$M$369) | G6: =SUMIF('02_КАЛЕНДАРЬ'!$B$5:$B$369,G$3,'02_КАЛЕНДАРЬ'!$M$5:$M$369) | H6: =SUMIF('02_КАЛЕНДАРЬ'!$B$5:$B$369,H$3,'02_КАЛЕНДАРЬ'!$M$5:$M$369) | I6: =SUMIF('02_КАЛЕНДАРЬ'!$B$5:$B$369,I$3,'02_КАЛЕНДАРЬ'!$M$5:$M$369) | J6: =SUMIF('02_КАЛЕНДАРЬ'!$B$5:$B$369,J$3,'02_КАЛЕНДАРЬ'!$M$5:$M$369) | K6: =SUMIF('02_КАЛЕНДАРЬ'!$B$5:$B$369,K$3,'02_КАЛЕНДАРЬ'!$M$5:$M$369) | ... O6: =SUMIF('02_КАЛЕНДАРЬ'!$B$5:$B$369,O$3,'02_КАЛЕНДАРЬ'!$M$5:$M$369) | P6: =SUM(D6:O6) | Q6: =P6/12 | R6: гостей
A7: REV.ALA.CHECK | B7: Кафе — а-ля карт | C7: Средний чек | D7: ='01_ВВОД'!$D$18 | E7: ='01_ВВОД'!$D$18 | F7: ='01_ВВОД'!$D$18 | G7: ='01_ВВОД'!$D$18 | H7: ='01_ВВОД'!$D$18 | I7: ='01_ВВОД'!$D$18 | J7: ='01_ВВОД'!$D$18 | K7: ='01_ВВОД'!$D$18 | ... O7: ='01_ВВОД'!$D$18 | P7: =AVERAGE(D7:O7) | Q7: =P7 | R7: руб./гость
A8: REV.ALA | B8: Кафе — а-ля карт | C8: Доходы а-ля карт | D8: =D6*D7 | E8: =E6*E7 | F8: =F6*F7 | G8: =G6*G7 | H8: =H6*H7 | I8: =I6*I7 | J8: =J6*J7 | K8: =K6*K7 | ... O8: =O6*O7 | P8: =SUM(D8:O8) | Q8: =P8/12 | R8: руб.
A10: REV.LUNCH.QTY | B10: Кафе — бизнес-ланч | C10: Гости бизнес-ланча | D10: =SUMIF('02_КАЛЕНДАРЬ'!$B$5:$B$369,D$3,'02_КАЛЕНДАРЬ'!$N$5:$N$369) | E10: =SUMIF('02_КАЛЕНДАРЬ'!$B$5:$B$369,E$3,'02_КАЛЕНДАРЬ'!$N$5:$N$369) | F10: =SUMIF('02_КАЛЕНДАРЬ'!$B$5:$B$369,F$3,'02_КАЛЕНДАРЬ'!$N$5:$N$369) | G10: =SUMIF('02_КАЛЕНДАРЬ'!$B$5:$B$369,G$3,'02_КАЛЕНДАРЬ'!$N$5:$N$369) | H10: =SUMIF('02_КАЛЕНДАРЬ'!$B$5:$B$369,H$3,'02_КАЛЕНДАРЬ'!$N$5:$N$369) | I10: =SUMIF('02_КАЛЕНДАРЬ'!$B$5:$B$369,I$3,'02_КАЛЕНДАРЬ'!$N$5:$N$369) | J10: =SUMIF('02_КАЛЕНДАРЬ'!$B$5:$B$369,J$3,'02_КАЛЕНДАРЬ'!$N$5:$N$369) | K10: =SUMIF('02_КАЛЕНДАРЬ'!$B$5:$B$369,K$3,'02_КАЛЕНДАРЬ'!$N$5:$N$369) | ... O10: =SUMIF('02_КАЛЕНДАРЬ'!$B$5:$B$369,O$3,'02_КАЛЕНДАРЬ'!$N$5:$N$369) | P10: =SUM(D10:O10) | Q10: =P10/12 | R10: гостей
A11: REV.LUNCH.CHECK | B11: Кафе — бизнес-ланч | C11: Средний чек | D11: ='01_ВВОД'!$D$28 | E11: ='01_ВВОД'!$D$28 | F11: ='01_ВВОД'!$D$28 | G11: ='01_ВВОД'!$D$28 | H11: ='01_ВВОД'!$D$28 | I11: ='01_ВВОД'!$D$28 | J11: ='01_ВВОД'!$D$28 | K11: ='01_ВВОД'!$D$28 | ... O11: ='01_ВВОД'!$D$28 | P11: =AVERAGE(D11:O11) | Q11: =P11 | R11: руб./гость
A12: REV.LUNCH | B12: Кафе — бизнес-ланч | C12: Доходы бизнес-ланча | D12: =D10*D11 | E12: =E10*E11 | F12: =F10*F11 | G12: =G10*G11 | H12: =H10*H11 | I12: =I10*I11 | J12: =J10*J11 | K12: =K10*K11 | ... O12: =O10*O11 | P12: =SUM(D12:O12) | Q12: =P12/12 | R12: руб.
A14: REV.DEL.QTY | B14: Кафе — доставка | C14: Заказы доставки | D14: =SUMIF('02_КАЛЕНДАРЬ'!$B$5:$B$369,D$3,'02_КАЛЕНДАРЬ'!$P$5:$P$369) | E14: =SUMIF('02_КАЛЕНДАРЬ'!$B$5:$B$369,E$3,'02_КАЛЕНДАРЬ'!$P$5:$P$369) | F14: =SUMIF('02_КАЛЕНДАРЬ'!$B$5:$B$369,F$3,'02_КАЛЕНДАРЬ'!$P$5:$P$369) | G14: =SUMIF('02_КАЛЕНДАРЬ'!$B$5:$B$369,G$3,'02_КАЛЕНДАРЬ'!$P$5:$P$369) | H14: =SUMIF('02_КАЛЕНДАРЬ'!$B$5:$B$369,H$3,'02_КАЛЕНДАРЬ'!$P$5:$P$369) | I14: =SUMIF('02_КАЛЕНДАРЬ'!$B$5:$B$369,I$3,'02_КАЛЕНДАРЬ'!$P$5:$P$369) | J14: =SUMIF('02_КАЛЕНДАРЬ'!$B$5:$B$369,J$3,'02_КАЛЕНДАРЬ'!$P$5:$P$369) | K14: =SUMIF('02_КАЛЕНДАРЬ'!$B$5:$B$369,K$3,'02_КАЛЕНДАРЬ'!$P$5:$P$369) | ... O14: =SUMIF('02_КАЛЕНДАРЬ'!$B$5:$B$369,O$3,'02_КАЛЕНДАРЬ'!$P$5:$P$369) | P14: =SUM(D14:O14) | Q14: =P14/12 | R14: заказов
A15: REV.DEL.CHECK | B15: Кафе — доставка | C15: Средний чек | D15: ='01_ВВОД'!$D$31 | E15: ='01_ВВОД'!$D$31 | F15: ='01_ВВОД'!$D$31 | G15: ='01_ВВОД'!$D$31 | H15: ='01_ВВОД'!$D$31 | I15: ='01_ВВОД'!$D$31 | J15: ='01_ВВОД'!$D$31 | K15: ='01_ВВОД'!$D$31 | ... O15: ='01_ВВОД'!$D$31 | P15: =AVERAGE(D15:O15) | Q15: =P15 | R15: руб./заказ
A16: REV.DEL | B16: Кафе — доставка | C16: Доходы доставки | D16: =D14*D15 | E16: =E14*E15 | F16: =F14*F15 | G16: =G14*G15 | H16: =H14*H15 | I16: =I14*I15 | J16: =J14*J15 | K16: =K14*K15 | ... O16: =O14*O15 | P16: =SUM(D16:O16) | Q16: =P16/12 | R16: руб.
A18: REV.PICK.QTY | B18: Кафе — самовывоз | C18: Заказы самовывоза | D18: =SUMIF('02_КАЛЕНДАРЬ'!$B$5:$B$369,D$3,'02_КАЛЕНДАРЬ'!$Q$5:$Q$369) | E18: =SUMIF('02_КАЛЕНДАРЬ'!$B$5:$B$369,E$3,'02_КАЛЕНДАРЬ'!$Q$5:$Q$369) | F18: =SUMIF('02_КАЛЕНДАРЬ'!$B$5:$B$369,F$3,'02_КАЛЕНДАРЬ'!$Q$5:$Q$369) | G18: =SUMIF('02_КАЛЕНДАРЬ'!$B$5:$B$369,G$3,'02_КАЛЕНДАРЬ'!$Q$5:$Q$369) | H18: =SUMIF('02_КАЛЕНДАРЬ'!$B$5:$B$369,H$3,'02_КАЛЕНДАРЬ'!$Q$5:$Q$369) | I18: =SUMIF('02_КАЛЕНДАРЬ'!$B$5:$B$369,I$3,'02_КАЛЕНДАРЬ'!$Q$5:$Q$369) | J18: =SUMIF('02_КАЛЕНДАРЬ'!$B$5:$B$369,J$3,'02_КАЛЕНДАРЬ'!$Q$5:$Q$369) | K18: =SUMIF('02_КАЛЕНДАРЬ'!$B$5:$B$369,K$3,'02_КАЛЕНДАРЬ'!$Q$5:$Q$369) | ... O18: =SUMIF('02_КАЛЕНДАРЬ'!$B$5:$B$369,O$3,'02_КАЛЕНДАРЬ'!$Q$5:$Q$369) | P18: =SUM(D18:O18) | Q18: =P18/12 | R18: заказов
A19: REV.PICK.CHECK | B19: Кафе — самовывоз | C19: Средний чек | D19: ='01_ВВОД'!$D$39 | E19: ='01_ВВОД'!$D$39 | F19: ='01_ВВОД'!$D$39 | G19: ='01_ВВОД'!$D$39 | H19: ='01_ВВОД'!$D$39 | I19: ='01_ВВОД'!$D$39 | J19: ='01_ВВОД'!$D$39 | K19: ='01_ВВОД'!$D$39 | ... O19: ='01_ВВОД'!$D$39 | P19: =AVERAGE(D19:O19) | Q19: =P19 | R19: руб./заказ
A20: REV.PICK | B20: Кафе — самовывоз | C20: Доходы самовывоза | D20: =D18*D19 | E20: =E18*E19 | F20: =F18*F19 | G20: =G18*G19 | H20: =H18*H19 | I20: =I18*I19 | J20: =J18*J19 | K20: =K18*K19 | ... O20: =O18*O19 | P20: =SUM(D20:O20) | Q20: =P20/12 | R20: руб.
A22: REV.HOTEL.QTY | B22: Кафе — гостиница | C22: Заказы гостиничного канала | D22: =SUMIF('02_КАЛЕНДАРЬ'!$B$5:$B$369,D$3,'02_КАЛЕНДАРЬ'!$R$5:$R$369) | E22: =SUMIF('02_КАЛЕНДАРЬ'!$B$5:$B$369,E$3,'02_КАЛЕНДАРЬ'!$R$5:$R$369) | F22: =SUMIF('02_КАЛЕНДАРЬ'!$B$5:$B$369,F$3,'02_КАЛЕНДАРЬ'!$R$5:$R$369) | G22: =SUMIF('02_КАЛЕНДАРЬ'!$B$5:$B$369,G$3,'02_КАЛЕНДАРЬ'!$R$5:$R$369) | H22: =SUMIF('02_КАЛЕНДАРЬ'!$B$5:$B$369,H$3,'02_КАЛЕНДАРЬ'!$R$5:$R$369) | I22: =SUMIF('02_КАЛЕНДАРЬ'!$B$5:$B$369,I$3,'02_КАЛЕНДАРЬ'!$R$5:$R$369) | J22: =SUMIF('02_КАЛЕНДАРЬ'!$B$5:$B$369,J$3,'02_КАЛЕНДАРЬ'!$R$5:$R$369) | K22: =SUMIF('02_КАЛЕНДАРЬ'!$B$5:$B$369,K$3,'02_КАЛЕНДАРЬ'!$R$5:$R$369) | ... O22: =SUMIF('02_КАЛЕНДАРЬ'!$B$5:$B$369,O$3,'02_КАЛЕНДАРЬ'!$R$5:$R$369) | P22: =SUM(D22:O22) | Q22: =P22/12 | R22: заказов
A23: REV.HOTEL.CHECK | B23: Кафе — гостиница | C23: Средний чек | D23: ='01_ВВОД'!$D$45 | E23: ='01_ВВОД'!$D$45 | F23: ='01_ВВОД'!$D$45 | G23: ='01_ВВОД'!$D$45 | H23: ='01_ВВОД'!$D$45 | I23: ='01_ВВОД'!$D$45 | J23: ='01_ВВОД'!$D$45 | K23: ='01_ВВОД'!$D$45 | ... O23: ='01_ВВОД'!$D$45 | P23: =AVERAGE(D23:O23) | Q23: =P23 | R23: руб./заказ
A24: REV.HOTEL | B24: Кафе — гостиница | C24: Доходы гостиничного канала | D24: =D22*D23 | E24: =E22*E23 | F24: =F22*F23 | G24: =G22*G23 | H24: =H22*H23 | I24: =I22*I23 | J24: =J22*J23 | K24: =K22*K23 | ... O24: =O22*O23 | P24: =SUM(D24:O24) | Q24: =P24/12 | R24: руб.
A26: REV.CAFE | B26: Кафе | C26: ИТОГО ДОХОДЫ КАФЕ | D26: =SUM(D8,D12,D16,D20,D24,D41) | E26: =SUM(E8,E12,E16,E20,E24,E41) | F26: =SUM(F8,F12,F16,F20,F24,F41) | G26: =SUM(G8,G12,G16,G20,G24,G41) | H26: =SUM(H8,H12,H16,H20,H24,H41) | I26: =SUM(I8,I12,I16,I20,I24,I41) | J26: =SUM(J8,J12,J16,J20,J24,J41) | K26: =SUM(K8,K12,K16,K20,K24,K41) | ... O26: =SUM(O8,O12,O16,O20,O24,O41) | P26: =SUM(D26:O26) | Q26: =P26/12 | R26: руб.
A28: УПУЩЕННАЯ ВЫРУЧКА КАФЕ ИЗ-ЗА БАНКЕТНЫХ ДНЕЙ
A29: REV.CAFE.POT | B29: Кафе | C29: Потенциальные доходы кафе без банкетных закрытий | D29: =SUMIF('02_КАЛЕНДАРЬ'!$B$5:$B$369,D$3,'02_КАЛЕНДАРЬ'!$L$5:$L$369)*'01_ВВОД'!$D$18+SUMIF('02_КАЛЕНДАРЬ'!$B$5:$B$369,D$3,'02_КАЛЕНДАРЬ'!$K$5:$K$369)*'01_ВВОД'!$D$26*'01_ВВОД'!$D$28+SUMIF('02_КАЛЕНДАРЬ'!$B$5:$B$369,D$3,'02_КАЛЕНДАРЬ'!$O$5:$O$369)*'01_ВВОД'!$D$31+COUNTIF('02_КАЛЕНДАРЬ'!$B$5:$B$369,D$3)*'01_ВВОД'!$D$40*'01_ВВОД'!$D$39+D24+D41 | E29: =SUMIF('02_КАЛЕНДАРЬ'!$B$5:$B$369,E$3,'02_КАЛЕНДАРЬ'!$L$5:$L$369)*'01_ВВОД'!$D$18+SUMIF('02_КАЛЕНДАРЬ'!$B$5:$B$369,E$3,'02_КАЛЕНДАРЬ'!$K$5:$K$369)*'01_ВВОД'!$D$26*'01_ВВОД'!$D$28+SUMIF('02_КАЛЕНДАРЬ'!$B$5:$B$369,E$3,'02_КАЛЕНДАРЬ'!$O$5:$O$369)*'01_ВВОД'!$D$31+COUNTIF('02_КАЛЕНДАРЬ'!$B$5:$B$369,E$3)*'01_ВВОД'!$D$40*'01_ВВОД'!$D$39+E24+E41 | F29: =SUMIF('02_КАЛЕНДАРЬ'!$B$5:$B$369,F$3,'02_КАЛЕНДАРЬ'!$L$5:$L$369)*'01_ВВОД'!$D$18+SUMIF('02_КАЛЕНДАРЬ'!$B$5:$B$369,F$3,'02_КАЛЕНДАРЬ'!$K$5:$K$369)*'01_ВВОД'!$D$26*'01_ВВОД'!$D$28+SUMIF('02_КАЛЕНДАРЬ'!$B$5:$B$369,F$3,'02_КАЛЕНДАРЬ'!$O$5:$O$369)*'01_ВВОД'!$D$31+COUNTIF('02_КАЛЕНДАРЬ'!$B$5:$B$369,F$3)*'01_ВВОД'!$D$40*'01_ВВОД'!$D$39+F24+F41 | G29: =SUMIF('02_КАЛЕНДАРЬ'!$B$5:$B$369,G$3,'02_КАЛЕНДАРЬ'!$L$5:$L$369)*'01_ВВОД'!$D$18+SUMIF('02_КАЛЕНДАРЬ'!$B$5:$B$369,G$3,'02_КАЛЕНДАРЬ'!$K$5:$K$369)*'01_ВВОД'!$D$26*'01_ВВОД'!$D$28+SUMIF('02_КАЛЕНДАРЬ'!$B$5:$B$369,G$3,'02_КАЛЕНДАРЬ'!$O$5:$O$369)*'01_ВВОД'!$D$31+COUNTIF('02_КАЛЕНДАРЬ'!$B$5:$B$369,G$3)*'01_ВВОД'!$D$40*'01_ВВОД'!$D$39+G24+G41 | H29: =SUMIF('02_КАЛЕНДАРЬ'!$B$5:$B$369,H$3,'02_КАЛЕНДАРЬ'!$L$5:$L$369)*'01_ВВОД'!$D$18+SUMIF('02_КАЛЕНДАРЬ'!$B$5:$B$369,H$3,'02_КАЛЕНДАРЬ'!$K$5:$K$369)*'01_ВВОД'!$D$26*'01_ВВОД'!$D$28+SUMIF('02_КАЛЕНДАРЬ'!$B$5:$B$369,H$3,'02_КАЛЕНДАРЬ'!$O$5:$O$369)*'01_ВВОД'!$D$31+COUNTIF('02_КАЛЕНДАРЬ'!$B$5:$B$369,H$3)*'01_ВВОД'!$D$40*'01_ВВОД'!$D$39+H24+H41 | I29: =SUMIF('02_КАЛЕНДАРЬ'!$B$5:$B$369,I$3,'02_КАЛЕНДАРЬ'!$L$5:$L$369)*'01_ВВОД'!$D$18+SUMIF('02_КАЛЕНДАРЬ'!$B$5:$B$369,I$3,'02_КАЛЕНДАРЬ'!$K$5:$K$369)*'01_ВВОД'!$D$26*'01_ВВОД'!$D$28+SUMIF('02_КАЛЕНДАРЬ'!$B$5:$B$369,I$3,'02_КАЛЕНДАРЬ'!$O$5:$O$369)*'01_ВВОД'!$D$31+COUNTIF('02_КАЛЕНДАРЬ'!$B$5:$B$369,I$3)*'01_ВВОД'!$D$40*'01_ВВОД'!$D$39+I24+I41 | J29: =SUMIF('02_КАЛЕНДАРЬ'!$B$5:$B$369,J$3,'02_КАЛЕНДАРЬ'!$L$5:$L$369)*'01_ВВОД'!$D$18+SUMIF('02_КАЛЕНДАРЬ'!$B$5:$B$369,J$3,'02_КАЛЕНДАРЬ'!$K$5:$K$369)*'01_ВВОД'!$D$26*'01_ВВОД'!$D$28+SUMIF('02_КАЛЕНДАРЬ'!$B$5:$B$369,J$3,'02_КАЛЕНДАРЬ'!$O$5:$O$369)*'01_ВВОД'!$D$31+COUNTIF('02_КАЛЕНДАРЬ'!$B$5:$B$369,J$3)*'01_ВВОД'!$D$40*'01_ВВОД'!$D$39+J24+J41 | K29: =SUMIF('02_КАЛЕНДАРЬ'!$B$5:$B$369,K$3,'02_КАЛЕНДАРЬ'!$L$5:$L$369)*'01_ВВОД'!$D$18+SUMIF('02_КАЛЕНДАРЬ'!$B$5:$B$369,K$3,'02_КАЛЕНДАРЬ'!$K$5:$K$369)*'01_ВВОД'!$D$26*'01_ВВОД'!$D$28+SUMIF('02_КАЛЕНДАРЬ'!$B$5:$B$369,K$3,'02_КАЛЕНДАРЬ'!$O$5:$O$369)*'01_ВВОД'!$D$31+COUNTIF('02_КАЛЕНДАРЬ'!$B$5:$B$369,K$3)*'01_ВВОД'!$D$40*'01_ВВОД'!$D$39+K24+K41 | ... O29: =SUMIF('02_КАЛЕНДАРЬ'!$B$5:$B$369,O$3,'02_КАЛЕНДАРЬ'!$L$5:$L$369)*'01_ВВОД'!$D$18+SUMIF('02_КАЛЕНДАРЬ'!$B$5:$B$369,O$3,'02_КАЛЕНДАРЬ'!$K$5:$K$369)*'01_ВВОД'!$D$26*'01_ВВОД'!$D$28+SUMIF('02_КАЛЕНДАРЬ'!$B$5:$B$369,O$3,'02_КАЛЕНДАРЬ'!$O$5:$O$369)*'01_ВВОД'!$D$31+COUNTIF('02_КАЛЕНДАРЬ'!$B$5:$B$369,O$3)*'01_ВВОД'!$D$40*'01_ВВОД'!$D$39+O24+O41 | P29: =SUM(D29:O29) | Q29: =P29/12 | R29: руб.
A30: REV.CAFE.LOST | B30: Кафе | C30: Упущенные доходы кафе из-за банкетов | D30: =D29-D26 | E30: =E29-E26 | F30: =F29-F26 | G30: =G29-G26 | H30: =H29-H26 | I30: =I29-I26 | J30: =J29-J26 | K30: =K29-K26 | ... O30: =O29-O26 | P30: =SUM(D30:O30) | Q30: =P30/12 | R30: руб.
A32: БИЗНЕС 2 — БАНКЕТЫ (ОТДЕЛЬНЫЙ ДОХОД)
A33: REV.BANQ.QTY | B33: Банкеты | C33: Количество банкетов | D33: =SUMIF('02_КАЛЕНДАРЬ'!$B$5:$B$369,D$3,'02_КАЛЕНДАРЬ'!$S$5:$S$369) | E33: =SUMIF('02_КАЛЕНДАРЬ'!$B$5:$B$369,E$3,'02_КАЛЕНДАРЬ'!$S$5:$S$369) | F33: =SUMIF('02_КАЛЕНДАРЬ'!$B$5:$B$369,F$3,'02_КАЛЕНДАРЬ'!$S$5:$S$369) | G33: =SUMIF('02_КАЛЕНДАРЬ'!$B$5:$B$369,G$3,'02_КАЛЕНДАРЬ'!$S$5:$S$369) | H33: =SUMIF('02_КАЛЕНДАРЬ'!$B$5:$B$369,H$3,'02_КАЛЕНДАРЬ'!$S$5:$S$369) | I33: =SUMIF('02_КАЛЕНДАРЬ'!$B$5:$B$369,I$3,'02_КАЛЕНДАРЬ'!$S$5:$S$369) | J33: =SUMIF('02_КАЛЕНДАРЬ'!$B$5:$B$369,J$3,'02_КАЛЕНДАРЬ'!$S$5:$S$369) | K33: =SUMIF('02_КАЛЕНДАРЬ'!$B$5:$B$369,K$3,'02_КАЛЕНДАРЬ'!$S$5:$S$369) | ... O33: =SUMIF('02_КАЛЕНДАРЬ'!$B$5:$B$369,O$3,'02_КАЛЕНДАРЬ'!$S$5:$S$369) | P33: =SUM(D33:O33) | Q33: =P33/12 | R33: банкетов
A34: REV.BANQ.PART | B34: Банкеты | C34: Участников на банкет | D34: ='01_ВВОД'!$D$53 | E34: ='01_ВВОД'!$D$53 | F34: ='01_ВВОД'!$D$53 | G34: ='01_ВВОД'!$D$53 | H34: ='01_ВВОД'!$D$53 | I34: ='01_ВВОД'!$D$53 | J34: ='01_ВВОД'!$D$53 | K34: ='01_ВВОД'!$D$53 | ... O34: ='01_ВВОД'!$D$53 | P34: =AVERAGE(D34:O34) | Q34: =P34 | R34: чел.
A35: REV.BANQ.CHECK | B35: Банкеты | C35: Средний чек на человека | D35: ='01_ВВОД'!$D$54 | E35: ='01_ВВОД'!$D$54 | F35: ='01_ВВОД'!$D$54 | G35: ='01_ВВОД'!$D$54 | H35: ='01_ВВОД'!$D$54 | I35: ='01_ВВОД'!$D$54 | J35: ='01_ВВОД'!$D$54 | K35: ='01_ВВОД'!$D$54 | ... O35: ='01_ВВОД'!$D$54 | P35: =AVERAGE(D35:O35) | Q35: =P35 | R35: руб./чел.
A36: REV.BANQ | B36: Банкеты | C36: ДОХОДЫ БАНКЕТОВ | D36: =D33*D34*D35 | E36: =E33*E34*E35 | F36: =F33*F34*F35 | G36: =G33*G34*G35 | H36: =H33*H34*H35 | I36: =I33*I34*I35 | J36: =J33*J34*J35 | K36: =K33*K34*K35 | ... O36: =O33*O34*O35 | P36: =SUM(D36:O36) | Q36: =P36/12 | R36: руб.
A38: REV.PROJECT | B38: Проект | C38: СОВОКУПНЫЕ ДОХОДЫ ПРОЕКТА | D38: =D26+D36 | E38: =E26+E36 | F38: =F26+F36 | G38: =G26+G36 | H38: =H26+H36 | I38: =I26+I36 | J38: =J26+J36 | K38: =K26+K36 | ... O38: =O26+O36 | P38: =SUM(D38:O38) | Q38: =P38/12 | R38: руб.
A39: REV.DINNER.QTY | B39: Кафе — гостиница | C39: Ужины гостиницы | D39: =SUMIF('02_КАЛЕНДАРЬ'!$B$5:$B$369,D$3,'02_КАЛЕНДАРЬ'!$U$5:$U$369) | E39: =SUMIF('02_КАЛЕНДАРЬ'!$B$5:$B$369,E$3,'02_КАЛЕНДАРЬ'!$U$5:$U$369) | F39: =SUMIF('02_КАЛЕНДАРЬ'!$B$5:$B$369,F$3,'02_КАЛЕНДАРЬ'!$U$5:$U$369) | G39: =SUMIF('02_КАЛЕНДАРЬ'!$B$5:$B$369,G$3,'02_КАЛЕНДАРЬ'!$U$5:$U$369) | H39: =SUMIF('02_КАЛЕНДАРЬ'!$B$5:$B$369,H$3,'02_КАЛЕНДАРЬ'!$U$5:$U$369) | I39: =SUMIF('02_КАЛЕНДАРЬ'!$B$5:$B$369,I$3,'02_КАЛЕНДАРЬ'!$U$5:$U$369) | J39: =SUMIF('02_КАЛЕНДАРЬ'!$B$5:$B$369,J$3,'02_КАЛЕНДАРЬ'!$U$5:$U$369) | K39: =SUMIF('02_КАЛЕНДАРЬ'!$B$5:$B$369,K$3,'02_КАЛЕНДАРЬ'!$U$5:$U$369) | ... O39: =SUMIF('02_КАЛЕНДАРЬ'!$B$5:$B$369,O$3,'02_КАЛЕНДАРЬ'!$U$5:$U$369) | P39: =SUM(D39:O39) | Q39: =P39/12 | R39: ужинов
A40: REV.DINNER.CHECK | B40: Кафе — гостиница | C40: Средний чек ужина | D40: ='01_ВВОД'!$D$121 | E40: ='01_ВВОД'!$D$121 | F40: ='01_ВВОД'!$D$121 | G40: ='01_ВВОД'!$D$121 | H40: ='01_ВВОД'!$D$121 | I40: ='01_ВВОД'!$D$121 | J40: ='01_ВВОД'!$D$121 | K40: ='01_ВВОД'!$D$121 | ... O40: ='01_ВВОД'!$D$121 | P40: =AVERAGE(D40:O40) | Q40: =P40 | R40: руб./ужин
A41: REV.DINNER | B41: Кафе — гостиница | C41: Доходы ужинов гостиницы | D41: =D39*D40 | E41: =E39*E40 | F41: =F39*F40 | G41: =G39*G40 | H41: =H39*H40 | I41: =I39*I40 | J41: =J39*J40 | K41: =K39*K40 | ... O41: =O39*O40 | P41: =SUM(D41:O41) | Q41: =P41/12 | R41: руб.

Sheet 04_СЕБЕСТОИМОСТЬ
A1: Себестоимость и прямые переменные расходы
A2: Себестоимость кафе рассчитана по направлениям; упаковка, доставщик и эквайринг показаны отдельно. Списания и инвентаризационные расхождения — редактируемые рабочие резервы.
D3: 1 | E3: 2 | F3: 3 | G3: 4 | H3: 5 | I3: 6 | J3: 7 | K3: 8 | L3: 9 | M3: 10 | N3: 11 | O3: 12
A4: Код | B4: Раздел | C4: Показатель | D4: Сен-26 | E4: Окт-26 | F4: Ноя-26 | G4: Дек-26 | H4: Янв-27 | I4: Фев-27 | J4: Мар-27 | K4: Апр-27 | L4: Май-27 | M4: Июн-27 | N4: Июл-27 | O4: Авг-27 | P4: Итого за год | Q4: Среднее за месяц | R4: Ед.
A5: БИЗНЕС 1 — КАФЕ: СЕБЕСТОИМОСТЬ ПРОДУКТОВ
A6: COGS.ALA.REV | B6: А-ля карт | C6: Доходы | D6: ='03_ДОХОДЫ'!D8 | E6: ='03_ДОХОДЫ'!E8 | F6: ='03_ДОХОДЫ'!F8 | G6: ='03_ДОХОДЫ'!G8 | H6: ='03_ДОХОДЫ'!H8 | I6: ='03_ДОХОДЫ'!I8 | J6: ='03_ДОХОДЫ'!J8 | K6: ='03_ДОХОДЫ'!K8 | ... O6: ='03_ДОХОДЫ'!O8 | P6: =SUM(D6:O6) | Q6: =P6/12 | R6: руб.
A7: COGS.ALA | B7: А-ля карт | C7: Food cost 30% | D7: =D6*'01_ВВОД'!$D$24 | E7: =E6*'01_ВВОД'!$D$24 | F7: =F6*'01_ВВОД'!$D$24 | G7: =G6*'01_ВВОД'!$D$24 | H7: =H6*'01_ВВОД'!$D$24 | I7: =I6*'01_ВВОД'!$D$24 | J7: =J6*'01_ВВОД'!$D$24 | K7: =K6*'01_ВВОД'!$D$24 | ... O7: =O6*'01_ВВОД'!$D$24 | P7: =SUM(D7:O7) | Q7: =P7/12 | R7: руб.
A8: COGS.LUNCH.REV | B8: Бизнес-ланч | C8: Доходы | D8: ='03_ДОХОДЫ'!D12 | E8: ='03_ДОХОДЫ'!E12 | F8: ='03_ДОХОДЫ'!F12 | G8: ='03_ДОХОДЫ'!G12 | H8: ='03_ДОХОДЫ'!H12 | I8: ='03_ДОХОДЫ'!I12 | J8: ='03_ДОХОДЫ'!J12 | K8: ='03_ДОХОДЫ'!K12 | ... O8: ='03_ДОХОДЫ'!O12 | P8: =SUM(D8:O8) | Q8: =P8/12 | R8: руб.
A9: COGS.LUNCH | B9: Бизнес-ланч | C9: Эффективный food cost | D9: =D8*'01_ВВОД'!$D$29 | E9: =E8*'01_ВВОД'!$D$29 | F9: =F8*'01_ВВОД'!$D$29 | G9: =G8*'01_ВВОД'!$D$29 | H9: =H8*'01_ВВОД'!$D$29 | I9: =I8*'01_ВВОД'!$D$29 | J9: =J8*'01_ВВОД'!$D$29 | K9: =K8*'01_ВВОД'!$D$29 | ... O9: =O8*'01_ВВОД'!$D$29 | P9: =SUM(D9:O9) | Q9: =P9/12 | R9: руб.
A10: COGS.DEL.REV | B10: Доставка | C10: Доходы | D10: ='03_ДОХОДЫ'!D16 | E10: ='03_ДОХОДЫ'!E16 | F10: ='03_ДОХОДЫ'!F16 | G10: ='03_ДОХОДЫ'!G16 | H10: ='03_ДОХОДЫ'!H16 | I10: ='03_ДОХОДЫ'!I16 | J10: ='03_ДОХОДЫ'!J16 | K10: ='03_ДОХОДЫ'!K16 | ... O10: ='03_ДОХОДЫ'!O16 | P10: =SUM(D10:O10) | Q10: =P10/12 | R10: руб.
A11: COGS.DEL | B11: Доставка | C11: Food cost 30% | D11: =D10*'01_ВВОД'!$D$35 | E11: =E10*'01_ВВОД'!$D$35 | F11: =F10*'01_ВВОД'!$D$35 | G11: =G10*'01_ВВОД'!$D$35 | H11: =H10*'01_ВВОД'!$D$35 | I11: =I10*'01_ВВОД'!$D$35 | J11: =J10*'01_ВВОД'!$D$35 | K11: =K10*'01_ВВОД'!$D$35 | ... O11: =O10*'01_ВВОД'!$D$35 | P11: =SUM(D11:O11) | Q11: =P11/12 | R11: руб.
A12: COGS.PICK.REV | B12: Самовывоз | C12: Доходы | D12: ='03_ДОХОДЫ'!D20 | E12: ='03_ДОХОДЫ'!E20 | F12: ='03_ДОХОДЫ'!F20 | G12: ='03_ДОХОДЫ'!G20 | H12: ='03_ДОХОДЫ'!H20 | I12: ='03_ДОХОДЫ'!I20 | J12: ='03_ДОХОДЫ'!J20 | K12: ='03_ДОХОДЫ'!K20 | ... O12: ='03_ДОХОДЫ'!O20 | P12: =SUM(D12:O12) | Q12: =P12/12 | R12: руб.
A13: COGS.PICK | B13: Самовывоз | C13: Эффективный food cost | D13: =D12*'01_ВВОД'!$D$42 | E13: =E12*'01_ВВОД'!$D$42 | F13: =F12*'01_ВВОД'!$D$42 | G13: =G12*'01_ВВОД'!$D$42 | H13: =H12*'01_ВВОД'!$D$42 | I13: =I12*'01_ВВОД'!$D$42 | J13: =J12*'01_ВВОД'!$D$42 | K13: =K12*'01_ВВОД'!$D$42 | ... O13: =O12*'01_ВВОД'!$D$42 | P13: =SUM(D13:O13) | Q13: =P13/12 | R13: руб.
A14: COGS.HOTEL.REV | B14: Гостиничный канал | C14: Доходы | D14: ='03_ДОХОДЫ'!D24 | E14: ='03_ДОХОДЫ'!E24 | F14: ='03_ДОХОДЫ'!F24 | G14: ='03_ДОХОДЫ'!G24 | H14: ='03_ДОХОДЫ'!H24 | I14: ='03_ДОХОДЫ'!I24 | J14: ='03_ДОХОДЫ'!J24 | K14: ='03_ДОХОДЫ'!K24 | ... O14: ='03_ДОХОДЫ'!O24 | P14: =SUM(D14:O14) | Q14: =P14/12 | R14: руб.
A15: COGS.HOTEL | B15: Гостиничный канал | C15: Food cost 50% | D15: =D14*'01_ВВОД'!$D$47 | E15: =E14*'01_ВВОД'!$D$47 | F15: =F14*'01_ВВОД'!$D$47 | G15: =G14*'01_ВВОД'!$D$47 | H15: =H14*'01_ВВОД'!$D$47 | I15: =I14*'01_ВВОД'!$D$47 | J15: =J14*'01_ВВОД'!$D$47 | K15: =K14*'01_ВВОД'!$D$47 | ... O15: =O14*'01_ВВОД'!$D$47 | P15: =SUM(D15:O15) | Q15: =P15/12 | R15: руб.
A16: COGS.BASE | B16: Кафе | C16: Продуктовая себестоимость до потерь | D16: =SUM(D7,D9,D11,D13,D15,D42) | E16: =SUM(E7,E9,E11,E13,E15,E42) | F16: =SUM(F7,F9,F11,F13,F15,F42) | G16: =SUM(G7,G9,G11,G13,G15,G42) | H16: =SUM(H7,H9,H11,H13,H15,H42) | I16: =SUM(I7,I9,I11,I13,I15,I42) | J16: =SUM(J7,J9,J11,J13,J15,J42) | K16: =SUM(K7,K9,K11,K13,K15,K42) | ... O16: =SUM(O7,O9,O11,O13,O15,O42) | P16: =SUM(D16:O16) | Q16: =P16/12 | R16: руб.
A17: COGS.SPOIL | B17: Кафе | C17: Списания и порча | D17: =D16*'01_ВВОД'!$D$16 | E17: =E16*'01_ВВОД'!$D$16 | F17: =F16*'01_ВВОД'!$D$16 | G17: =G16*'01_ВВОД'!$D$16 | H17: =H16*'01_ВВОД'!$D$16 | I17: =I16*'01_ВВОД'!$D$16 | J17: =J16*'01_ВВОД'!$D$16 | K17: =K16*'01_ВВОД'!$D$16 | ... O17: =O16*'01_ВВОД'!$D$16 | P17: =SUM(D17:O17) | Q17: =P17/12 | R17: руб.
A18: COGS.INV | B18: Кафе | C18: Инвентаризационные расхождения | D18: =D16*'01_ВВОД'!$D$17 | E18: =E16*'01_ВВОД'!$D$17 | F18: =F16*'01_ВВОД'!$D$17 | G18: =G16*'01_ВВОД'!$D$17 | H18: =H16*'01_ВВОД'!$D$17 | I18: =I16*'01_ВВОД'!$D$17 | J18: =J16*'01_ВВОД'!$D$17 | K18: =K16*'01_ВВОД'!$D$17 | ... O18: =O16*'01_ВВОД'!$D$17 | P18: =SUM(D18:O18) | Q18: =P18/12 | R18: руб.
A19: COGS.TOTAL | B19: Кафе | C19: ИТОГО СЕБЕСТОИМОСТЬ КАФЕ | D19: =SUM(D16:D18) | E19: =SUM(E16:E18) | F19: =SUM(F16:F18) | G19: =SUM(G16:G18) | H19: =SUM(H16:H18) | I19: =SUM(I16:I18) | J19: =SUM(J16:J18) | K19: =SUM(K16:K18) | ... O19: =SUM(O16:O18) | P19: =SUM(D19:O19) | Q19: =P19/12 | R19: руб.
A20: GROSS.PROFIT | B20: Кафе | C20: ВАЛОВАЯ ПРИБЫЛЬ КАФЕ | D20: ='03_ДОХОДЫ'!D26-D19 | E20: ='03_ДОХОДЫ'!E26-E19 | F20: ='03_ДОХОДЫ'!F26-F19 | G20: ='03_ДОХОДЫ'!G26-G19 | H20: ='03_ДОХОДЫ'!H26-H19 | I20: ='03_ДОХОДЫ'!I26-I19 | J20: ='03_ДОХОДЫ'!J26-J19 | K20: ='03_ДОХОДЫ'!K26-K19 | ... O20: ='03_ДОХОДЫ'!O26-O19 | P20: =SUM(D20:O20) | Q20: =P20/12 | R20: руб.
A22: БИЗНЕС 1 — КАФЕ: ПРОЧИЕ ПРЯМЫЕ ПЕРЕМЕННЫЕ РАСХОДЫ
A23: VAR.COURIER | B23: Доставка | C23: Доставщик | D23: ='03_ДОХОДЫ'!D14*'01_ВВОД'!$D$36 | E23: ='03_ДОХОДЫ'!E14*'01_ВВОД'!$D$36 | F23: ='03_ДОХОДЫ'!F14*'01_ВВОД'!$D$36 | G23: ='03_ДОХОДЫ'!G14*'01_ВВОД'!$D$36 | H23: ='03_ДОХОДЫ'!H14*'01_ВВОД'!$D$36 | I23: ='03_ДОХОДЫ'!I14*'01_ВВОД'!$D$36 | J23: ='03_ДОХОДЫ'!J14*'01_ВВОД'!$D$36 | K23: ='03_ДОХОДЫ'!K14*'01_ВВОД'!$D$36 | ... O23: ='03_ДОХОДЫ'!O14*'01_ВВОД'!$D$36 | P23: =SUM(D23:O23) | Q23: =P23/12 | R23: руб.
A24: VAR.DEL.PACK | B24: Доставка | C24: Упаковка | D24: ='03_ДОХОДЫ'!D14*'01_ВВОД'!$D$37 | E24: ='03_ДОХОДЫ'!E14*'01_ВВОД'!$D$37 | F24: ='03_ДОХОДЫ'!F14*'01_ВВОД'!$D$37 | G24: ='03_ДОХОДЫ'!G14*'01_ВВОД'!$D$37 | H24: ='03_ДОХОДЫ'!H14*'01_ВВОД'!$D$37 | I24: ='03_ДОХОДЫ'!I14*'01_ВВОД'!$D$37 | J24: ='03_ДОХОДЫ'!J14*'01_ВВОД'!$D$37 | K24: ='03_ДОХОДЫ'!K14*'01_ВВОД'!$D$37 | ... O24: ='03_ДОХОДЫ'!O14*'01_ВВОД'!$D$37 | P24: =SUM(D24:O24) | Q24: =P24/12 | R24: руб.
A25: VAR.PICK.PACK | B25: Самовывоз | C25: Упаковка | D25: ='03_ДОХОДЫ'!D18*'01_ВВОД'!$D$43 | E25: ='03_ДОХОДЫ'!E18*'01_ВВОД'!$D$43 | F25: ='03_ДОХОДЫ'!F18*'01_ВВОД'!$D$43 | G25: ='03_ДОХОДЫ'!G18*'01_ВВОД'!$D$43 | H25: ='03_ДОХОДЫ'!H18*'01_ВВОД'!$D$43 | I25: ='03_ДОХОДЫ'!I18*'01_ВВОД'!$D$43 | J25: ='03_ДОХОДЫ'!J18*'01_ВВОД'!$D$43 | K25: ='03_ДОХОДЫ'!K18*'01_ВВОД'!$D$43 | ... O25: ='03_ДОХОДЫ'!O18*'01_ВВОД'!$D$43 | P25: =SUM(D25:O25) | Q25: =P25/12 | R25: руб.
A26: VAR.HOTEL.PACK | B26: Гостиница | C26: Упаковка / расходники | D26: ='03_ДОХОДЫ'!D22*'01_ВВОД'!$D$48 | E26: ='03_ДОХОДЫ'!E22*'01_ВВОД'!$D$48 | F26: ='03_ДОХОДЫ'!F22*'01_ВВОД'!$D$48 | G26: ='03_ДОХОДЫ'!G22*'01_ВВОД'!$D$48 | H26: ='03_ДОХОДЫ'!H22*'01_ВВОД'!$D$48 | I26: ='03_ДОХОДЫ'!I22*'01_ВВОД'!$D$48 | J26: ='03_ДОХОДЫ'!J22*'01_ВВОД'!$D$48 | K26: ='03_ДОХОДЫ'!K22*'01_ВВОД'!$D$48 | ... O26: ='03_ДОХОДЫ'!O22*'01_ВВОД'!$D$48 | P26: =SUM(D26:O26) | Q26: =P26/12 | R26: руб.
A27: VAR.ACQ | B27: Кафе | C27: Эквайринг | D27: ='03_ДОХОДЫ'!D8*'01_ВВОД'!$D$25*'01_ВВОД'!$D$14+'03_ДОХОДЫ'!D12*'01_ВВОД'!$D$30*'01_ВВОД'!$D$14+'03_ДОХОДЫ'!D16*'01_ВВОД'!$D$38*'01_ВВОД'!$D$14+'03_ДОХОДЫ'!D20*'01_ВВОД'!$D$44*'01_ВВОД'!$D$14+'03_ДОХОДЫ'!D24*'01_ВВОД'!$D$49*'01_ВВОД'!$D$14 | E27: ='03_ДОХОДЫ'!E8*'01_ВВОД'!$D$25*'01_ВВОД'!$D$14+'03_ДОХОДЫ'!E12*'01_ВВОД'!$D$30*'01_ВВОД'!$D$14+'03_ДОХОДЫ'!E16*'01_ВВОД'!$D$38*'01_ВВОД'!$D$14+'03_ДОХОДЫ'!E20*'01_ВВОД'!$D$44*'01_ВВОД'!$D$14+'03_ДОХОДЫ'!E24*'01_ВВОД'!$D$49*'01_ВВОД'!$D$14 | F27: ='03_ДОХОДЫ'!F8*'01_ВВОД'!$D$25*'01_ВВОД'!$D$14+'03_ДОХОДЫ'!F12*'01_ВВОД'!$D$30*'01_ВВОД'!$D$14+'03_ДОХОДЫ'!F16*'01_ВВОД'!$D$38*'01_ВВОД'!$D$14+'03_ДОХОДЫ'!F20*'01_ВВОД'!$D$44*'01_ВВОД'!$D$14+'03_ДОХОДЫ'!F24*'01_ВВОД'!$D$49*'01_ВВОД'!$D$14 | G27: ='03_ДОХОДЫ'!G8*'01_ВВОД'!$D$25*'01_ВВОД'!$D$14+'03_ДОХОДЫ'!G12*'01_ВВОД'!$D$30*'01_ВВОД'!$D$14+'03_ДОХОДЫ'!G16*'01_ВВОД'!$D$38*'01_ВВОД'!$D$14+'03_ДОХОДЫ'!G20*'01_ВВОД'!$D$44*'01_ВВОД'!$D$14+'03_ДОХОДЫ'!G24*'01_ВВОД'!$D$49*'01_ВВОД'!$D$14 | H27: ='03_ДОХОДЫ'!H8*'01_ВВОД'!$D$25*'01_ВВОД'!$D$14+'03_ДОХОДЫ'!H12*'01_ВВОД'!$D$30*'01_ВВОД'!$D$14+'03_ДОХОДЫ'!H16*'01_ВВОД'!$D$38*'01_ВВОД'!$D$14+'03_ДОХОДЫ'!H20*'01_ВВОД'!$D$44*'01_ВВОД'!$D$14+'03_ДОХОДЫ'!H24*'01_ВВОД'!$D$49*'01_ВВОД'!$D$14 | I27: ='03_ДОХОДЫ'!I8*'01_ВВОД'!$D$25*'01_ВВОД'!$D$14+'03_ДОХОДЫ'!I12*'01_ВВОД'!$D$30*'01_ВВОД'!$D$14+'03_ДОХОДЫ'!I16*'01_ВВОД'!$D$38*'01_ВВОД'!$D$14+'03_ДОХОДЫ'!I20*'01_ВВОД'!$D$44*'01_ВВОД'!$D$14+'03_ДОХОДЫ'!I24*'01_ВВОД'!$D$49*'01_ВВОД'!$D$14 | J27: ='03_ДОХОДЫ'!J8*'01_ВВОД'!$D$25*'01_ВВОД'!$D$14+'03_ДОХОДЫ'!J12*'01_ВВОД'!$D$30*'01_ВВОД'!$D$14+'03_ДОХОДЫ'!J16*'01_ВВОД'!$D$38*'01_ВВОД'!$D$14+'03_ДОХОДЫ'!J20*'01_ВВОД'!$D$44*'01_ВВОД'!$D$14+'03_ДОХОДЫ'!J24*'01_ВВОД'!$D$49*'01_ВВОД'!$D$14 | K27: ='03_ДОХОДЫ'!K8*'01_ВВОД'!$D$25*'01_ВВОД'!$D$14+'03_ДОХОДЫ'!K12*'01_ВВОД'!$D$30*'01_ВВОД'!$D$14+'03_ДОХОДЫ'!K16*'01_ВВОД'!$D$38*'01_ВВОД'!$D$14+'03_ДОХОДЫ'!K20*'01_ВВОД'!$D$44*'01_ВВОД'!$D$14+'03_ДОХОДЫ'!K24*'01_ВВОД'!$D$49*'01_ВВОД'!$D$14 | ... O27: ='03_ДОХОДЫ'!O8*'01_ВВОД'!$D$25*'01_ВВОД'!$D$14+'03_ДОХОДЫ'!O12*'01_ВВОД'!$D$30*'01_ВВОД'!$D$14+'03_ДОХОДЫ'!O16*'01_ВВОД'!$D$38*'01_ВВОД'!$D$14+'03_ДОХОДЫ'!O20*'01_ВВОД'!$D$44*'01_ВВОД'!$D$14+'03_ДОХОДЫ'!O24*'01_ВВОД'!$D$49*'01_ВВОД'!$D$14 | P27: =SUM(D27:O27) | Q27: =P27/12 | R27: руб.
A28: VAR.TOTAL | B28: Кафе | C28: ИТОГО ПРОЧИЕ ПРЯМЫЕ РАСХОДЫ | D28: =SUM(D23:D27,D29) | E28: =SUM(E23:E27,E29) | F28: =SUM(F23:F27,F29) | G28: =SUM(G23:G27,G29) | H28: =SUM(H23:H27,H29) | I28: =SUM(I23:I27,I29) | J28: =SUM(J23:J27,J29) | K28: =SUM(K23:K27,K29) | ... O28: =SUM(O23:O27,O29) | P28: =SUM(D28:O28) | Q28: =P28/12 | R28: руб.
A29: VAR.DINNER.PACK | B29: Гостиница — ужины | C29: Упаковка / расходники ужинов | D29: ='03_ДОХОДЫ'!D39*'01_ВВОД'!$D$123 | E29: ='03_ДОХОДЫ'!E39*'01_ВВОД'!$D$123 | F29: ='03_ДОХОДЫ'!F39*'01_ВВОД'!$D$123 | G29: ='03_ДОХОДЫ'!G39*'01_ВВОД'!$D$123 | H29: ='03_ДОХОДЫ'!H39*'01_ВВОД'!$D$123 | I29: ='03_ДОХОДЫ'!I39*'01_ВВОД'!$D$123 | J29: ='03_ДОХОДЫ'!J39*'01_ВВОД'!$D$123 | K29: ='03_ДОХОДЫ'!K39*'01_ВВОД'!$D$123 | ... O29: ='03_ДОХОДЫ'!O39*'01_ВВОД'!$D$123 | P29: =SUM(D29:O29) | Q29: =P29/12 | R29: руб.
A30: CONTRIB.CAFE | B30: Кафе | C30: МАРЖИНАЛЬНЫЙ ДОХОД КАФЕ | D30: =D20-D28 | E30: =E20-E28 | F30: =F20-F28 | G30: =G20-G28 | H30: =H20-H28 | I30: =I20-I28 | J30: =J20-J28 | K30: =K20-K28 | ... O30: =O20-O28 | P30: =SUM(D30:O30) | Q30: =P30/12 | R30: руб.
A32: БИЗНЕС 2 — БАНКЕТЫ: ПРЯМОЙ ФИНАНСОВЫЙ РЕЗУЛЬТАТ
A33: BANQ.REV | B33: Банкеты | C33: Доходы банкетов | D33: ='03_ДОХОДЫ'!D36 | E33: ='03_ДОХОДЫ'!E36 | F33: ='03_ДОХОДЫ'!F36 | G33: ='03_ДОХОДЫ'!G36 | H33: ='03_ДОХОДЫ'!H36 | I33: ='03_ДОХОДЫ'!I36 | J33: ='03_ДОХОДЫ'!J36 | K33: ='03_ДОХОДЫ'!K36 | ... O33: ='03_ДОХОДЫ'!O36 | P33: =SUM(D33:O33) | Q33: =P33/12 | R33: руб.
A34: BANQ.COGS | B34: Банкеты | C34: Себестоимость 40% | D34: =D33*'01_ВВОД'!$D$55 | E34: =E33*'01_ВВОД'!$D$55 | F34: =F33*'01_ВВОД'!$D$55 | G34: =G33*'01_ВВОД'!$D$55 | H34: =H33*'01_ВВОД'!$D$55 | I34: =I33*'01_ВВОД'!$D$55 | J34: =J33*'01_ВВОД'!$D$55 | K34: =K33*'01_ВВОД'!$D$55 | ... O34: =O33*'01_ВВОД'!$D$55 | P34: =SUM(D34:O34) | Q34: =P34/12 | R34: руб.
A35: BANQ.GROSS | B35: Банкеты | C35: Валовая прибыль | D35: =D33-D34 | E35: =E33-E34 | F35: =F33-F34 | G35: =G33-G34 | H35: =H33-H34 | I35: =I33-I34 | J35: =J33-J34 | K35: =K33-K34 | ... O35: =O33-O34 | P35: =SUM(D35:O35) | Q35: =P35/12 | R35: руб.
A36: BANQ.AGENT | B36: Банкеты | C36: Комиссия агента 10% | D36: =D33*'01_ВВОД'!$D$56 | E36: =E33*'01_ВВОД'!$D$56 | F36: =F33*'01_ВВОД'!$D$56 | G36: =G33*'01_ВВОД'!$D$56 | H36: =H33*'01_ВВОД'!$D$56 | I36: =I33*'01_ВВОД'!$D$56 | J36: =J33*'01_ВВОД'!$D$56 | K36: =K33*'01_ВВОД'!$D$56 | ... O36: =O33*'01_ВВОД'!$D$56 | P36: =SUM(D36:O36) | Q36: =P36/12 | R36: руб.
A37: BANQ.ACQ | B37: Банкеты | C37: Эквайринг | D37: =D33*'01_ВВОД'!$D$57*'01_ВВОД'!$D$14 | E37: =E33*'01_ВВОД'!$D$57*'01_ВВОД'!$D$14 | F37: =F33*'01_ВВОД'!$D$57*'01_ВВОД'!$D$14 | G37: =G33*'01_ВВОД'!$D$57*'01_ВВОД'!$D$14 | H37: =H33*'01_ВВОД'!$D$57*'01_ВВОД'!$D$14 | I37: =I33*'01_ВВОД'!$D$57*'01_ВВОД'!$D$14 | J37: =J33*'01_ВВОД'!$D$57*'01_ВВОД'!$D$14 | K37: =K33*'01_ВВОД'!$D$57*'01_ВВОД'!$D$14 | ... O37: =O33*'01_ВВОД'!$D$57*'01_ВВОД'!$D$14 | P37: =SUM(D37:O37) | Q37: =P37/12 | R37: руб.
A38: BANQ.RESULT | B38: Банкеты | C38: ФИНАНСОВЫЙ РЕЗУЛЬТАТ ДО НАЛОГА | D38: =D35-D36-D37 | E38: =E35-E36-E37 | F38: =F35-F36-F37 | G38: =G35-G36-G37 | H38: =H35-H36-H37 | I38: =I35-I36-I37 | J38: =J35-J36-J37 | K38: =K35-K36-K37 | ... O38: =O35-O36-O37 | P38: =SUM(D38:O38) | Q38: =P38/12 | R38: руб.
A40: CONTRIB.PROJECT | B40: Проект | C40: СОВОКУПНЫЙ МАРЖИНАЛЬНЫЙ РЕЗУЛЬТАТ | D40: =D30+D38 | E40: =E30+E38 | F40: =F30+F38 | G40: =G30+G38 | H40: =H30+H38 | I40: =I30+I38 | J40: =J30+J38 | K40: =K30+K38 | ... O40: =O30+O38 | P40: =SUM(D40:O40) | Q40: =P40/12 | R40: руб.
A41: COGS.DINNER.REV | B41: Гостиница — ужины | C41: Доходы ужинов | D41: ='03_ДОХОДЫ'!D41 | E41: ='03_ДОХОДЫ'!E41 | F41: ='03_ДОХОДЫ'!F41 | G41: ='03_ДОХОДЫ'!G41 | H41: ='03_ДОХОДЫ'!H41 | I41: ='03_ДОХОДЫ'!I41 | J41: ='03_ДОХОДЫ'!J41 | K41: ='03_ДОХОДЫ'!K41 | ... O41: ='03_ДОХОДЫ'!O41 | P41: =SUM(D41:O41) | Q41: =P41/12 | R41: руб.
A42: COGS.DINNER | B42: Гостиница — ужины | C42: Food cost ужинов 30% — как a-la carte | D42: =D41*'01_ВВОД'!$D$122 | E42: =E41*'01_ВВОД'!$D$122 | F42: =F41*'01_ВВОД'!$D$122 | G42: =G41*'01_ВВОД'!$D$122 | H42: =H41*'01_ВВОД'!$D$122 | I42: =I41*'01_ВВОД'!$D$122 | J42: =J41*'01_ВВОД'!$D$122 | K42: =K41*'01_ВВОД'!$D$122 | ... O42: =O41*'01_ВВОД'!$D$122 | P42: =SUM(D42:O42) | Q42: =P42/12 | R42: руб.

Sheet 05_ФОТ
A1: ФОТ, НДФЛ, страховые взносы и подрядчики
A2: Ставки сотрудников заданы как суммы «на руки». Gross = Net / (1 − НДФЛ). Страховые взносы начисляются только на штат; бухгалтерия и ИТ — самозанятые.
A4: ДЕТАЛИЗАЦИЯ ШТАТА КАФЕ
